Workbook

Sheet INFORME EXTERNOS 2022
B2: ENERO 2022
B4: VICTOR VALENCIA | K4: POR CONSIGNACION
B5: CONSIGNACIONES | C5: CONTRATO | D5: % PROPIETARIO | E5: INMUEBLE | F5: CANON | G5: % | H5: COMISION | I5: CONSIGNO | J5: INVENTARIO | K5: EJECUTIVO | L5: CONTRATO | M5: INMUEBLE | N5: CANON | O5: % | P5: COMISION
B6: =CAPTACIONES!L29 -> 23 | C6: 13102 | D6: 0.1 | E6: PENTAGRAMA 2216 | F6: 1500000 | G6: 0.06 | H6: =G6*F6 -> 90000 | I6: PORTADA | J6: CAMILO | K6: STEFANY AGUDELO | L6: 13033 | M6: CARRERA 84 35-62 APT 301 | N6: 1200000 | O6: 0.05 | P6: =O6*N6 -> 60000
C7: 13098 | D7: 0.1 | E7: LOS CABOS 1101 SUBROGACION | F7: 1800000 | G7: 0.05 | H7: =G7*F7 -> 90000 | I7: PORTADA | J7: CAMILO | K7: STEFANY AGUDELO | L7: 13121 | M7: PORTAL DE LAS AMERICAS 206 | N7: 2300000 | O7: 0.05 | P7: =O7*N7 -> 115000
C8: 13110 | D8: 0.1 | E8: CALLE 42 C N° 63C - 35 AP 901 | F8: 2750000 | G8: 0.1 | H8: =G8*F8 -> 275000 | I8: VICTOR VALENCIA | J8: CAMILO | K8: LUISA MARIN | L8: 13052 | M8: CIUDADELA DEL PARQUE 1821 | N8: 1450000 | O8: 0.05 | P8: =O8*N8 -> 72500
C9: 13118 | D9: 0.1 | E9: RODEO VERDE 622 | F9: 1100000 | G9: 0.06 | H9: =G9*F9 -> 66000 | I9: PORTADA | J9: CAMILO | K9: LUISA MARIN
M10: TOTAL | N10: =SUM(N6:N8) -> 4950000 | O10: TOTAL | P10: =SUM(P6:P8) -> 247500
B11: TOTAL | F11: =SUM(F6:F10) -> 7150000 | G11: TOTAL | H11: =SUM(H6:H10) -> 521000 | M11: TOTAL--------------------------------------> | P11: =H11+P10 -> 768500
B13: ALEJANDRA RESTREPO | K13: POR CONSIGNACION
B14: CONSIGNACIONES | C14: CONTRATO | D14: % PROPIETARIO | E14: INMUEBLE | F14: CANON | G14: % | H14: COMISION | I14: CONSIGNO | J14: INVENTARIO | K14: EJECUTIVO | L14: CONTRATO | M14: INMUEBLE | N14: CANON | O14: % | P14: COMISION
B15: =CAPTACIONES!L47 -> 13 | C15: 12961 | D15: 0.1 | E15: LOS CABOS 630 | F15: 1700000 | G15: 0.05 | H15: =G15*F15 -> 85000 | I15: PORTADA | J15: CAMILO | K15: CRISTIAN | L15: 12947 | M15: ENTRE BOSQUES 1616 | N15: 1700000 | O15: 0.04 | P15: =O15*N15 -> 68000
C16: 12956 | D16: 0.1 | E16: EDIFICIO BENIDORM 302 | F16: 1350000 | G16: 0.04 | H16: =G16*F16 -> 54000 | I16: JULIAN SOLIS | J16: CAMILO | K16: CRISTIAN
C17: 12993 | D17: 0.1 | E17: VILLA DE ABURRA 201 | F17: 1850000 | G17: 0.08 | H17: =G17*F17 -> 148000 | I17: ALEJANDRA RESTREPO | J17: CAMILO | K17: STEFANNY AGUDELO
C18: DESISTIDO | D18: 0.1 | E18: CARRERA 83A 32EE-44 SUBROGACIÓN - 1.300.000 | I18: PORTADA | J18: El inquilino actual desiste de la subrogación y continua en el inmueble | K18: STEFANNY AGUDELO
C19: DESISTIDO | D19: 0.1 | E19: RODEO VERDE 912 - 1.200.000 | J19: Vendieron el carro y no les servia el sector así | K19: STEFANNY AGUDELO
C20: DESISTIDO | D20: 0.1 | E20: CAMINO DEL PARQUE 2512 - 1.700.000 | J20: Propietario lo arrendo | K20: ANDREA
C21: DESISTIDO | D21: 0.1 | E21: MARQUEZ DE CACERES 802 - 1.500.000 | J21: Propietario lo arrendo | K21: STEFANY AGUDELO
C22: DESISTIDO | D22: 0.1 | E22: ARBOLEDA DEL RODEO 1808 - 1.400.000 | J22: Inquilinio desistio | K22: STEFANNY AGUDELO
M23: TOTAL | N23: =SUM(N15:N17) -> 1700000 | O23: TOTAL | P23: =SUM(P15:P16) -> 68000
B24: TOTAL | F24: =SUM(F15:F23) -> 4900000 | G24: TOTAL | H24: =SUM(H15:H23) -> 287000 | M24: TOTAL--------------------------------------> | P24: =H24+P23 -> 355000
B27: JULIAN SOLIS | K27: POR CONSIGNACION
B28: CONSIGNACIONES | C28: CONTRATO | D28: % PROPIETARIO | E28: INMUEBLE | F28: CANON | G28: % | H28: COMISION | I28: CONSIGNO | J28: INVENTARIO | K28: EJECUTIVO | L28: CONTRATO | M28: INMUEBLE | N28: CANON | O28: % | P28: COMISION
B29: =CAPTACIONES!L64 -> 13 | C29: 12924 | D29: 0.1 | E29: GUADARRAMA 526 | F29: 1600000 | G29: 0.08 | H29: =G29*F29 -> 128000 | I29: JULIAN SOLIS | J29: CAMILO | K29: ANDREA | L29: 12956 | M29: EDIFICIO BENIDORM 302 | N29: 1350000 | O29: 0.04 | P29: =O29*N29 -> 54000
C30: 12970 | D30: 0.1 | E30: ALPES PLAZA 1803 | F30: 1650000 | G30: 0.04 | H30: =G30*F30 -> 66000 | I30: LUIS CORREA | J30: CAMILO | K30: CRISTIAN
C31: 12996 | D31: 0.1 | E31: LOS CABOS 322 | F31: 2100000 | G31: 0.05 | H31: =G31*F31 -> 105000 | I31: PORTADA | J31: CAMILO | K31: STEFANNY AGUDELO
C32: 12963 | D32: 0.1 | E32: ZAPZURRO 201 | F32: 1850000 | G32: 0.04 | H32: =G32*F32 -> 74000 | I32: ALONSO | J32: CAMILO | K32: ANDREA
C33: 13005 | D33: 0.1 | E33: CAMINO DEL PARQUE 2512 | F33: 1700000 | G33: 0.04 | H33: =G33*F33 -> 68000 | I33: ALEJANDRO VILLEGAS | J33: CAMILO | K33: STEFANNY AGUDELO
C34: 13026 | D34: 0.1 | E34: LOS CABOS 9926 | F34: 1950000 | G34: 0.05 | H34: =G34*F34 -> 97500 | I34: PORTADA | J34: CAMILO | K34: STEFANY AGUDELO
C35: 13033 | D35: 0.1 | E35: CARRERA 84 35-62 APT 301 | F35: 1200000 | G35: 0.04 | H35: =G35*F35 -> 48000 | I35: VICTOR VALENCIA | J35: CAMILO | K35: ANDREA
C36: 13117 | D36: 0.1 | E36: RODEO VERDE 725 SUBROGACION | F36: 1200000 | G36: 0.04 | H36: =G36*F36 -> 48000 | I36: PORTADA | J36: CAMILO | K36: LUISA MARIN
C37: DESISTIDO | D37: 0.1 | E37: ARBOLEDA DEL RODEO 1808 - 1.400.000 | I37: YERMANY | J37: El cliente decide seguir buscando, no estaba convencido | K37: LUISA MARIN
C38: DESISTIDO | D38: 0.1 | E38: CALLE 35 80-42 - 2.200.000 | J38: iInquillino desiste porque dice que ya no le sirve sin parqueadero | K38: LUISA MARIN
C39: DESISTIDO | D39: 0.1 | E39: ANKARA 401 - 2.300.000 | J39: Propietario dice que no puede enviar composición accionaria de la empresa que aparece como propietaria, dice que no le queda posible. | K39: AURA POSSO | M39: TOTAL | N39: =SUM(N29:N33) -> 1350000 | O39: TOTAL | P39: =SUM(P29:P33) -> 54000
B40: TOTAL | F40: =SUM(F29:F39) -> 13250000 | G40: TOTAL | H40: =SUM(H29:H39) -> 634500 | M40: TOTAL--------------------------------------> | P40: =H40+P39 -> 688500
B42: FELIPE ECHEVERRI | K42: POR CONSIGNACION
B43: CONSIGNACIONES | C43: CONTRATO | D43: % PROPIETARIO | E43: INMUEBLE | F43: CANON | G43: % | H43: COMISION | I43: CONSIGNO | J43: INVENTARIO | K43: EJECUTIVO | L43: CONTRATO | M43: INMUEBLE | N43: CANON | O43: % | P43: COMISION
B44: =CAPTACIONES!L81 -> 0
M49: TOTAL | N49: =SUM(N44:N48) -> 0 | O49: TOTAL | P49: =SUM(P44:P48) -> 0
B50: TOTAL | F50: =SUM(F44:F49) -> 0 | G50: TOTAL | H50: =SUM(H44:H49) -> 0 | M50: TOTAL--------------------------------------> | P50: =H50+P49 -> 0
...

Sheet INFORME INTERNAS Y ADMON 2022
B2: ENERO 2022
B4: ENERO 2022 - LUISA MARIN
B5: CONTRATO | C5: PROPIETARIO | D5: OBSERVACIONES | E5: INMUEBLE | F5: CANON | G5: % | H5: LUISA | I5: EXTERNO
B6: 13117 | C6: 0.1 | D6: LUISA MARIN | E6: RODEO VERDE 725 SUBROGACION | F6: 1200000 | G6: 0.02 | H6: =G6*F6 -> 24000 | I6: JULIAN SOLIS
B7: 13110 | C7: 0.1 | D7: LUISA MARIN | E7: CALLE 42 C N° 63C - 35 AP 901 | F7: 2750000 | G7: 0.02 | H7: =G7*F7 -> 55000 | I7: VICTOR VALENCIA
B8: 13118 | C8: 0.1 | D8: LUISA MARIN | E8: RODEO VERDE 622 | F8: 1100000 | G8: 0.02 | H8: =G8*F8 -> 22000 | I8: VICTOR VALENCIA
B9: 12932 | C9: 0.1 | D9: LUISA MARIN | E9: ENTREVIENTOS 309 | F9: 900000 | G9: 0.02 | H9: =G9*F9 -> 18000 | I9: BELLO
B10: 12938 | C10: 0.1 | D10: LUISA MARIN | E10: PUERTA MADERO 408 | F10: 1000000 | G10: 0.02 | H10: =G10*F10 -> 20000 | I10: BELLO
B11: 12953 | C11: 0.1 | D11: LUISA MARIN | E11: CALLE 42B 58 - 23 301 | F11: 720000 | G11: 0.02 | H11: =G11*F11 -> 14400 | I11: BELLO
B12: 12954 | C12: 0.1 | D12: LUISA MARIN | E12: NORDICA 2709 | F12: 1700000 | G12: 0.02 | H12: =G12*F12 -> 34000 | I12: BELLO
B13: 12958 | C13: 0.1 | D13: LUISA MARIN | E13: PUERTO PARAISO 2306 | F13: 1300000 | G13: 0.02 | H13: =G13*F13 -> 26000 | I13: BELLO
B14: 12998 | C14: 0.1 | D14: LUISA MARIN | E14: PUERTO PARAISO 1207 | F14: 1150000 | G14: 0.02 | H14: =G14*F14 -> 23000 | I14: BELLO
B15: 12991 | C15: 0.1 | D15: LUISA MARIN | E15: PUERTO PARAISO 1609 | F15: 1200000 | G15: 0.02 | H15: =G15*F15 -> 24000 | I15: BELLO
B16: DESISTIDO | C16: El cliente decide seguir buscando, no estaba convencido | D16: LUISA MARIN | E16: ARBOLEDA DEL RODEO 1808 - 1.400.000 | I16: JULIAN SOLIS
B17: DESISTIDO | C17: iInquillino desiste porque dice que ya no le sirve sin parqueadero | D17: LUISA MARIN | E17: CALLE 35 80-42 - 2.200.000 | I17: JULIAN SOLIS
E18: TOTAL-----------------------------------> | F18: =SUM(F6:F17) -> 13020000 | H18: =SUM(H1:H17) -> 260400
B20: ENERO 2022 - STEFANNY AGUDELO
B21: CONTRATO | C21: PROPIETARIO | D21: OBSERVACIONES | E21: INMUEBLE | F21: CANON | G21: % | H21: STEFANNY | I21: EXTERNO
B22: 12993 | C22: 0.1 | D22: STEFANNY AGUDELO | E22: VILLA DE ABURRA 201 | F22: 1850000 | G22: 0.02 | H22: =G22*F22 -> 37000 | I22: ALEJANDRA RESTREPO
B23: 12996 | C23: 0.1 | D23: STEFANNY AGUDELO | E23: LOS CABOS 322 | F23: 2100000 | G23: 0.02 | H23: =G23*F23 -> 42000 | I23: JULIAN SOLIS
B24: 13005 | C24: 0.1 | D24: STEFANNY AGUDELO | E24: CAMINO DEL PARQUE 2512 | F24: 1700000 | G24: 0.02 | H24: =G24*F24 -> 34000 | I24: JULIAN SOLIS
B25: 13026 | C25: 0.1 | D25: STEFANNY AGUDELO | E25: LOS CABOS 9926 | F25: 1950000 | G25: 0.02 | H25: =G25*F25 -> 39000 | I25: JULIAN SOLIS
B26: 13102 | C26: 0.1 | D26: STEFANNY AGUDELO | E26: PENTAGRAMA 2216 | F26: 1500000 | G26: 0.02 | H26: =G26*F26 -> 30000 | I26: VICTOR VALENCIA
B27: 13098 | C27: 0.1 | D27: STEFANNY AGUDELO | E27: LOS CABOS 1101 SUBROGACION | F27: 1800000 | G27: 0.02 | H27: =G27*F27 -> 36000 | I27: VICTOR VALENCIA
B28: 13094 | C28: 0.08 | D28: STEFANNY AGUDELO | E28: CALLE 65C 94 - 51 AP 101 | F28: 750000 | G28: 0.01 | H28: =G28*F28 -> 7500 | I28: PORTADA
B29: DESISTIDO | C29: El inquilino actual desiste de la subrogación y continua en el inmueble | D29: STEFANNY AGUDELO | E29: CARRERA 83A 32EE-44 SUBROGACIÓN - 1.300.000 | I29: ALEJANDRA RESTREPO
B30: DESISTIDO | C30: Vendieron el carro y no les servia el sector así | D30: STEFANNY AGUDELO | E30: RODEO VERDE 912 - 1.200.000 | I30: ALEJANDRA RESTREPO
B31: DESISTIDO | C31: Propietario lo arrendo | D31: STEFANNY AGUDELO | E31: MARQUEZ DE CACERES 802 - 1.500.000 | I31: ALEJANDRA RESTREPO
B32: DESISTIDO | C32: Inquilinio desistio | D32: STEFANNY AGUDELO | E32: ARBOLEDA DEL RODEO 1808 - 1.400.000 | I32: ALEJANDRA RESTREPO
E33: TOTAL-----------------------------------> | F33: =SUM(F22:F32) -> 11650000 | H33: =SUM(H22:H32) -> 225500
B35: ENERO 2022 - AURA POSSO
B36: CONTRATO | C36: PROPIETARIO | D36: OBSERVACIONES | E36: INMUEBLE | F36: CANON | G36: % | H36: AURA | I36: EXTERNO
B38: DESISTIDO | C38: Propietario dice que no puede enviar composición accionaria de la empresa que aparece como propietaria, dice que no le queda posible. | D38: AURA POSSO | E38: ANKARA 401 - 2.300.000 | I38: JULIAN SOLIS
E39: TOTAL-----------------------------------> | F39: =SUM(F37:F38) -> 0 | H39: =SUM(H37:H38) -> 0
B41: ENERO 2022 - PORTADA
B42: CONTRATO | C42: PROPIETARIO | D42: OBSERVACIONES | E42: INMUEBLE | F42: CANON | G42: % | H42: PORTADA | I42: EXTERNO
E48: TOTAL-----------------------------------> | F48: =SUM(F43:F47) -> 0 | H48: =SUM(H43:H47) -> 0
B50: CONSOLIDADO ENERO LAURELES 2022- VERÓNICA ORTIZ
B51: CONTRATO | C51: PROPIETARIO | D51: OBSERVACIONES | E51: INMUEBLE | F51: CANON | G51: % | H51: VERÓNICA | I51: EXTERNO | J51: FACTURADO
B52: 12993 | C52: 0.1 | D52: STEFANNY AGUDELO | E52: VILLA DE ABURRA 201 | F52: 1850000 | I52: ALEJANDRA RESTREPO | J52: CATHERINE
...

Sheet CAPTACIONES
B2: ENERO 2022
B4: VICTOR VALENCIA - ENERO 2022
B5: FECHA | C5: TIPO | D5: APTO | E5: SECTOR | F5: VALOR | G5: PORTERO O DIRECTO | H5: AVISOS | I5: FOTOS | J5: CT ARRIENDO | K5: CT VENTA | L5: ASESOR
B6: 19/1/2022 | C6: APTO | D6: BALCONES DE CONQUISTADORES 201 | E6: CONQUISTADORES | F6: 3000000 | G6: PORTERO | H6: SI | I6: SI | J6: 1 | L6: LUISA
B7: 19/1/2022 | C7: APTO | D7: BALCONES DE CONQUISTADORES 501 | E7: CONQUISTADORES | F7: 2500000 | G7: PORTERO | H7: SI | I7: SI | J7: 1 | L7: LUISA
B8: 19/1/2022 | C8: APTO | D8: BALCONES DE CONQUISTADORES 601 | E8: CONQUISTADORES | F8: 2500000 | G8: PORTERO | H8: SI | I8: SI | J8: 1 | L8: LUISA
B9: 19/1/2022 | C9: APTO | D9: BALCONES DE CONQUISTADORES 901 | E9: CONQUISTADORES | F9: 2500000 | G9: PORTERO | H9: SI | I9: SI | J9: 1 | L9: LUISA
B10: 19/1/2022 | C10: APTO | D10: BALCONES DE CONQUISTADORES 1001 | E10: CONQUISTADORES | F10: 2500000 | G10: PORTERO | H10: SI | I10: SI | J10: 1 | L10: LUISA
B11: 19/1/2022 | C11: APTO | D11: EDF ACACIAS 401 | E11: LAURELES | F11: 1750000 | G11: DIRECTO | H11: SI | I11: SI | J11: 1 | L11: LUISA
B12: 19/1/2022 | C12: APTO | D12: MASSAMAGREL 301 | E12: LA CASTELLANA | F12: 2600000 | G12: PORTERO | H12: SI | I12: SI | J12: 1 | L12: STEFANNY
B13: 19/1/2022 | C13: APTO | D13: BALCONES DE CONQUISTADORES 301 | E13: CONQUISTADORES | F13: 2500000 | G13: PORTERO | H13: SI | I13: SI | J13: 1 | L13: STEFANNY
B14: 19/1/2022 | C14: APTO | D14: BALCONES DE CONQUISTADORES 401 | E14: CONQUISTADORES | F14: 2500000 | G14: PORTERO | H14: SI | I14: SI | J14: 1 | L14: STEFANNY
B15: 19/1/2022 | C15: APTO | D15: BALCONES DE CONQUISTADORES 801 | E15: CONQUISTADORES | F15: 2500000 | G15: PORTERO | H15: SI | I15: SI | J15: 1 | L15: STEFANNY
B16: 19/1/2022 | C16: APTO | D16: BALCONES DE CONQUISTADORES 701 | E16: CONQUISTADORES | F16: 2500000 | G16: PORTERO | H16: SI | I16: SI | J16: 1 | L16: STEFANNY
B17: 19/1/2022 | C17: APTO | D17: BALCONES DE CONQUISTADORES 1101 | E17: CONQUISTADORES | F17: 2500000 | G17: PORTERO | H17: SI | I17: SI | J17: 1 | L17: STEFANNY
... B25: 25/01/2022 | C25: APARTAMENTO | D25: ANUNCIACION NIÑA MARIA 401 | E25: SIMON BOLIVAR | F25: 2700000 | G25: PORTERO | H25: SI | I25: SI | J25: 1 | L25: STEFANNY
B26: 25/01/2022 | C26: APARTAMENTO | D26: SAN FERNANDO 304 | E26: SAN FERNANDO | F26: 75000000 | G26: DIRECTO | H26: NO | I26: SI | K26: 1 | L26: VENTAS
B27: 25/01/2022 | C27: APARTAMENTO | D27: EIDIFICIO TORRECILLAS DE LAURELES 701 | E27: LAURELES | F27: 485000000 | G27: DIRECTO | H27: NO | I27: SI | K27: 1 | L27: VENTAS
B28: 25/01/2022 | C28: CASA | D28: CALLE 33AA 82-19 | E28: CASTELLANA | F28: 1700000000 | G28: DIRECTO | H28: NO | I28: SI | K28: 1 | L28: VENTAS
B29: TOTAL | J29: =SUM(J6:J27) -> 20 | K29: =SUM(K6:K28) -> 3 | L29: =J29+K29 -> 23
B31: ALEJANDRA RESTREPO - ENERO 2022
B32: FECHA | C32: TIPO | D32: APTO | E32: SECTOR | F32: VALOR | G32: PORTERO O DIRECTO | H32: AVISOS | I32: FOTOS | J32: CT ARRIENDO | K32: CT VENTA | L32: ASESOR
B33: 28/12/2021 | C33: APARTAMENTO | D33: CR 78 45 12 AP 402 | E33: VELODROMO | F33: 1350000 | G33: DIRECTO | H33: SI | I33: SI | J33: 1 | L33: CRISTIAN
B34: 28/12/2021 | C34: APARTAESTUDIO | D34: CR 78 45 12 AP 203 | E34: VELODROMO | F34: 1100000 | G34: DIRECTO | H34: SI | I34: SI | J34: 1 | L34: STEFANNY
B35: 28/12/2021 | C35: APARTAMENTO | D35: SAN MIGUEL 803 | E35: LOMA DE LOS BERNAL | F35: 1800000 | G35: PORTERO | H35: NO | I35: SI | J35: 1 | L35: STEFANNY
B36: 28/12/2021 | C36: APARTAMENTO | D36: CL 44B 86 12 AP 202 | E36: LA AMERICA | F36: 1300000 | G36: DIRECTO | H36: SI | I36: SI | J36: 1 | L36: ANDREA
B37: 44652 | C37: CASA | D37: CR 71 45B 21 | E37: FLORIDA NUEVA | F37: 2000000 | G37: DIRECTO | H37: SI | I37: SI | J37: 1 | L37: ANDREA
B38: 44652 | C38: APARTAESTUDIO | D38: MARQUES DE CASERES 802 | E38: CONQUISTADORES | F38: 1500000 | G38: PORTERO | H38: SI | I38: SI | J38: 1 | L38: CRISTIAN
B39: 44348 | C39: APARTAMENTO | D39: OASIS DE LOS BERNAL 405 | E39: LOMA DE LOS BERNAL | F39: 1500000 | G39: PORTERO | H39: SI | I39: SI | J39: 1 | L39: AURA
B40: 44348 | C40: APARTAMENTO | D40: CALLE 32C 81A 90 201 | E40: VILLA DE ABURRA | F40: 2000000 | G40: DIRECTO | H40: SI | I40: SI | J40: 1 | L40: AURA
B41: 44501 | C41: APARTAMENTO | D41: CR 79A 20A 155 201 | E41: BELEN LA GLORIA | F41: 1400000 | G41: DIRECTO | H41: SI | I41: SI | J41: 1 | L41: LUISA
B42: 44501 | C42: APARTAMENTO | D42: CR83A 37D 11 101 | E42: SIMON BOLIVAR | F42: 2300000 | G42: DIRECTO | H42: SI | I42: SI | J42: 1 | L42: STEFANNY
B43: 44501 | C43: APARTAMENTO | D43: JARDIN DE LAURELES 419 | E43: LAURELES | F43: 3800000 | G43: PORTERO | H43: SI | I43: SI | J43: 1 | L43: STEFANNY
B44: 19/1/2021 | C44: APARTAMENTO | D44: OASIS DE LOS BERNAL 919 | E44: LOMA DE LOS BERNAL | F44: 280000000 | G44: PORTERO | H44: SI | I44: SI | K44: 1 | L44: VENTAS
B45: 24/01/2021 | C45: APARTAMENTO | D45: BISSÓ 909 | E45: LOMA DE LOS BERNAL | F45: 495000000 | G45: PORTERO | H45: NO | I45: SI | K45: 1 | L45: VENTAS
B47: TOTAL | J47: =SUM(J33:J46) -> 11 | K47: =SUM(K33:K46) -> 2 | L47: =J47+K47 -> 13
B49: JULIAN SOLIS - ENERO 2022
B50: FECHA | C50: TIPO | D50: APTO | E50: SECTOR | F50: VALOR | G50: PORTERO O DIRECTO | H50: AVISOS | I50: FOTOS | J50: CT ARRIENDO | K50: CT VENTA | L50: ASESOR
B51: 30/12/2021 | C51: CASA | D51: CR 78 29 38 3 PISO | E51: BELEN PARQUE | F51: 2000000 | G51: DIRECTO | H51: SI | I51: SI | J51: 1 | L51: CRISTIAN
B52: 44682 | C52: CASA | D52: CR 65 # 1 SUR 111 | E52: MALLORCA | F52: 2000000 | G52: DIRECTO | H52: NO | I52: SI | J52: 1 | L52: CRISTIAN
...

Sheet PLAN CELULAR
A2: ASESOR | C2: MAYO
A3: STEFANNY AGUDELO | B3: 40500 | C3: X
A4: JESSICA ORTIZ | B4: 40500 | C4: X
A5: JOHANA PEÑA | B5: 40500 | C5: X
A6: VICTOR EDUARDO VALENICA | B6: 40500 | C6: X
A7: JULIAN SOLIS | B7: 40500 | C7: X
A8: ALEJANDRA RESTREPO | B8: 40500 | C8: X
A9: LUIS CORREA | B9: 40500 | C9: X
A10: FABER MENDEZ | B10: 40500 | C10: X
A11: TOTAL | B11: =SUM(B3:B10) -> 324000
A13: ASESOR | C13: JUNIO
A14: STEFANNY AGUDELO | B14: 40500 | C14: X
A15: JESSICA ORTIZ | B15: 40500 | C15: X
A16: JOHANA PEÑA | B16: 40500 | C16: X
A17: VICTOR EDUARDO VALENICA | B17: 40500 | C17: X
A18: JULIAN SOLIS | B18: 40500 | C18: X
A19: ALEJANDRA RESTREPO | B19: 40500 | C19: X
A20: DANIELA MONTOYA | B20: 40500 | C20: X
A21: LUIS CORREA | B21: 40500 | C21: X
A22: TOTAL | B22: =SUM(B14:B21) -> 324000
A24: ASESOR | C24: JULIO
A25: STEFANNY AGUDELO | B25: 40500 | C25: X
A26: JESSICA ORTIZ | B26: 40500 | C26: X
A27: VICTOR VALENICA | B27: 40500 | C27: X
A28: JULIAN SOLIS | B28: 40500 | C28: X
A29: ALEJANDRA RESTREPO | B29: 40500 | C29: X
A30: TOTAL | B30: =SUM(B25:B29) -> 202500
A32: ASESOR | C32: AGOSTO
A33: STEFANNY AGUDELO | B33: 40500 | C33: X
A34: JESSICA ORTIZ | B34: 40500 | C34: X
A35: VICTOR VALENICA | B35: 40500 | C35: X
A36: JULIAN SOLIS | B36: 40500 | C36: X
A37: ALEJANDRA RESTREPO | B37: VACACIONES
A38: JACKSON ARIAS | B38: 40500 | C38: X
A39: SANTIAGO HOYOS | B39: 44100 | C39: X
A40: TOTAL | B40: =SUM(B33:B39) -> 246600
A42: ASESOR | C42: SEPTIEMBRE
A43: STEFANNY AGUDELO | B43: 40500 | C43: X
A44: JESSICA ORTIZ | B44: 40500 | C44: X
A45: VICTOR VALENICA | B45: 40500 | C45: X
...

Sheet AUTORIZACIONES OTROSI - 6 MESES
B2: MAYO
B3: NEGOCIOS | C3: OTRO SI | D3: DURACION | E3: CTO FISICO | F3: OTRO | G3: MOTIVO
B4: SUBROGACION LA CASTELLANA CARRERA 83 N° 34C - 16 | C4: X | G4: NO SE RECIBE POR ARRGELOS, SE DEBE CAMBIAR FECHA DE INICIO
B5: ARCO 301 | C5: X | G5: INQUILINA VENIA DE QUIBDO POR EL PARO ARMADO NO PUDO VIAJAR, SE CAMBIA FECHA DE INICIO
B6: CARRERA 80A 40-39 | C6: X | E6: X | G6: PROPIETARIO MANIFIESTA SOLO QUERER FIRMAR FISICA YA QUE SIEMPRE TRABAJA ASI SUS CONTRATOS, QUEDO ERRADO EN EL % DE INCREMENTO, ES UN NEGOCIO COMERCIAL
B7: NANTES 401 | G7: CTO PROPIETARIO AL 8%, SE RESPETA PORCENTAJE CON EL QUE SE TRABAJA ESTE PROPIETARIO.
B8: SURBOGACION NANTES 302 | G8: CTO PROPIETARIO AL 8%, SE RESPETA PORCENTAJE CON EL QUE SE TRABAJA ESTE PROPIETARIO.
B9: FUENTE CAMPESTRE 808 | G9: CTO PROPIETARIO AL 9% SE RESPETA PORCENTAJE CON EL QUE SE TRABAJA ESTE PROPIETARIO.
B10: TORRE AVELLANA 701 | D10: 7 MESES | G10: ES UN ACUERDO ENTRE PROP E INQUILIN
B11: VITENZA 1412 | G11: COMISION AL 8% PARA QUE SE QUEDE CON PORTADA
B12: ZAMORANO 101 | C12: X | G12: CAMBIO DE COMISION Y FECHA DE PAGO AL 12% PAGOS LOS 3 - OTROSI INQUILINO POR CAMBIO DE FEHCA
B13: AMARANTA 401 | E13: X | G13: PROP SOLO QUIERE FIRMAR FISICO Y DESEA AUTENTICAR
B14: CAMINO DEL PARQUE 2304 | E14: X | G14: ES UN APTO QUE SE LE QUITO A ESCALA Y ERA DE UNICA FORMA QUE NOS LO DABA
B15: BALCONES DE LA CONSOLATA | D15: 6MESES | G15: EL INQUILINO HABIA DESISTIDO PERO LA PROPIETARIA ACEPTO CONTRATO POR ESTE TIEMPO
B17: JUNIO
B18: NEGOCIOS | C18: OTRO SI | D18: DURACION | E18: CTO FISICO | F18: OTRO | G18: MOTIVO
B19: NO SE PRESENTARO NOVEDADES
B21: JULIO
B22: NEGOCIOS | C22: OTRO SI | D22: DURACION | E22: CTO FISICO | F22: OTRO | G22: MOTIVO
B23: NO SE PRESENTARO NOVEDADES
B25: AGOSTO
B26: NEGOCIOS | C26: OTRO SI | D26: DURACION | E26: CTO FISICO | F26: OTRO | G26: MOTIVO
B27: ALCAZAR DE SAN FRANCISCO 502 | C27: X | G27: OTROSI CTO ADMON E INQUILINO POR CLAUSULA ADICIONAL
B28: CARRERA 81 # 40-72 | F28: X | G28: PAGO EL 5 DE CADA MES POR QUE EL PROP SE IBA A QUITAR POR LA FECHA DE PAGO
B29: JAIMAR 104 | C29: X | G29: CAMBIO DE FECHA DE INICIO
B30: CALLE 40 81A 44 | C30: X | G30: CAMBIO DE CANON PROP
B31: TORRE LAUREL 401 | D31: X | G31: CTO A 6 MESES POR SOLICITUD DE LA PROPIETARIA
B32: MONTELIMAR 905 | C32: X | G32: POR CAMBIO FECHA DE INICIO AUN NO ESTABA PINTADO
B33: RODEO VERDE 523 | D33: X | G33: CONTRATO 6 MESES POR SOLICITUD DEL CLIENTE PROP AUTORIZA
B36: SEPTIEMBRE
B37: NEGOCIOS | C37: OTRO SI | D37: DURACION | E37: CTO FISICO | F37: OTRO | G37: MOTIVO
