Workbook

Sheet INFORME 2019
A1: INFORME ENERO 2019 ENVIGADO
A3: ALEJANDRO BEDOYA
A4: CONSIGNACIONES | B4: CONTRATO | C4: %PROPIETARIO | D4: INMUEBLE | E4: CANON | F4: % | G4: comision | H4: ASESOR 2 | I4: EJECUTIVA | J4: OBSERVACIONES | K4: CONTRATO | L4: INMUEBLE | M4: CANON | N4: %
A5: 20+3 | B5: 7738 | C5: 0.1 | D5: NATIVO ARENA 1408 - 2.500.000 | E5: 2500000 | F5: 0.12 | G5: =E5*F5 -> 300000 | H5: ALEJANDRO BEDOYA | I5: MELBI CASTRILLON | K5: 7815 | L5: ZARZAMORA 705 | M5: 2250000 | N5: 0.05 | O5: =M5*N5 -> 112500
B6: 7749 | C6: 0.1 | D6: PUERTO LUNA 813 -SUBROGACION | E6: 1350000 | F6: 0.07 | G6: =F6*E6 -> 94500 | H6: PORTADA | I6: MELBI CASTRILLON | K6: 7816 | L6: PUERTO LUNA 604 | M6: 1500000 | N6: 0.05 | O6: =M6*N6 -> 75000
B7: 7812 | C7: 0.1 | D7: CUBIK 406 SUBROGACION | E7: 1770000 | F7: 0.07 | G7: =F7*E7 -> 123900 | H7: PORTADA | I7: RONALD MENDEZ
B8: 7782 | C8: 0.1 | D8: CHATEL 308 - 2.000.000 | E8: 2000000 | F8: 0.12 | G8: =E8*F8 -> 240000 | H8: ALEJANDRO BEDOYA | I8: RONALD MENDEZ
B9: 7789 | C9: 0.1 | D9: ENTREPARQUES 623 RECIBIMIENTO | E9: 1850000 | F9: 0.07 | G9: =E9*F9 -> 129500 | H9: PORTADA | I9: RONALD MENDEZ
B10: 7813 | C10: 0.1 | D10: NATIVO ARENA 1004 - RECIBIMIENTO | E10: 3750000 | F10: 0.07 | G10: =E10*F10 -> 262500 | H10: PORTADA | I10: MELBI CASTRILLON
B11: 7829 | C11: 0.1 | D11: TERRAZINO ZUÑIGA 902 REUBICACION | E11: 2600000 | F11: 0.12 | G11: =E11*F11 -> 312000 | H11: ALEJANDRO BEDOYA | I11: MELBI CASTRILLON
B12: 7834 | C12: 0.08 | D12: BRUJA BONITA 408 - 2.500.000 | E12: 2500000 | F12: 0.1 | G12: =E12*F12 -> 250000 | H12: ALEJANDRO BEDOYA | I12: MELBI CASTRILLON
B13: 7856 | C13: 0.1 | D13: BIOCITY GRAND 1517 | E13: 1800000 | F13: 0.07 | G13: =E13*F13 -> 126000 | H13: ANDRES MIRANDA | I13: RONALD MENDEZ
B14: DESISTIDO | C14: 0.1 | D14: PAMELA - 2.200.000 TIERRA GRATA ESMERALDAL | I14: MELBI CASTRILLON
B15: DESISTIDO | C15: 0.1 | D15: PUERTO LUNA 1606 - 1.300.000 | I15: RONALD MENDEZ
O16: =SUM(O5:O15) -> 187500
D17: TOTAL | E17: =SUM(E5:E16) -> 20120000 | F17: TOTAL | G17: =SUM(G5:G15) -> 1838400 | L17: TOTAL--------------------------------------> | O17: =G17+O16 -> 2025900
A19: JUAN DIEGO HERRERA
A20: CONSIGNACIONES | B20: CONTRATO | C20: %PROPIETARIO | D20: INMUEBLE | E20: CANON | F20: % | G20: comision | H20: ASESOR 2 | I20: EJECUTIVA | J20: OBSERVACIONES | K20: CONTRATO | L20: INMUEBLE | M20: CANON | N20: %
A21: 20+5 | B21: 7762 | C21: 0.1 | D21: BRUJAS CAMPESTRE 905 REUBICACION | E21: 1850000 | F21: 0.07 | G21: =E21*F21 -> 129500 | H21: ANDRES MIRANDA | I21: MELBI CASTRILLON | K21: 7768 | L21: BOSQUES DEL ESMERALDAL 184 | M21: 2500000 | N21: 0.05 | O21: =N21*M21 -> 125000
B22: 7785 | C22: 0.1 | D22: VILLA CRISTINA 501 RECIBIMIENTO | E22: 1800000 | F22: 0.07 | G22: =F22*E22 -> 126000 | H22: PORTADA | I22: MELBI CASTRILLON
B23: 7752 | C23: 0.1 | D23: CALIFORNIA 1907 | E23: 1450000 | F23: 0.07 | G23: =F23*E23 -> 101500 | H23: JUAN PABLO VILLA | I23: MELBI CASTRILLON
B24: 7854 | C24: 0.1 | D24: AMARELLO IN 1505 | E24: 1800000 | F24: 0.07 | G24: =E24*F24 -> 126000 | H24: PORTADA | I24: MELBI CASTRILLON
B25: DESISTIDO | C25: 0.1 | D25: PORTAL DEL CERRO 507 - 1.150.000 | G25: =E25*F25 -> 0 | I25: MELBI CASTRILLON
O26: =SUM(O21:O23) -> 125000
D27: TOTAL | E27: =SUM(E21:E26) -> 6900000 | F27: TOTAL | G27: =SUM(G21:G26) -> 483000 | L27: TOTAL--------------------------------------> | O27: =O26+G27 -> 608000
A29: JUAN PABLO VILLA
A30: CONSIGNACIONES | B30: CONTRATO | C30: %PROPIETARIO | D30: INMUEBLE | E30: CANON | F30: % | G30: comision | H30: ASESOR 2 | I30: EJECUTIVA | J30: OBSERVACIONES | K30: CONTRATO | L30: INMUEBLE | M30: CANON | N30: %
A31: 5 | B31: DESISTIDO | C31: 0.1 | D31: BIOCITY GRAN 804 - 1.600.000 | G31: =E31*F31 -> 0 | I31: MELBI CASTRILLON | K31: 7752 | L31: CALIFORNIA 1907 | M31: 1450000 | N31: 0.04 | O31: =N31*M31 -> 58000
C32: 0.1 | G32: =E32*F32 -> 0
C33: 0.1 | G33: =F33*E33 -> 0
C34: 0.1 | G34: =F34*E34 -> 0 | O34: =SUM(O31:O33) -> 58000
D35: TOTAL | E35: =SUM(E31:E34) -> 0 | F35: TOTAL | G35: =SUM(G31:G34) -> 0 | L35: TOTAL--------------------------------------> | O35: =O34+G35 -> 58000
A37: ANDRES MIRANDA
A38: CONSIGNACIONES | B38: CONTRATO | C38: %PROPIETARIO | D38: INMUEBLE | E38: CANON | F38: % | G38: comision | H38: ASESOR 2 | I38: EJECUTIVA | J38: OBSERVACIONES | K38: CONTRATO | L38: INMUEBLE | M38: CANON | N38: %
A39: 20+3 | B39: 7730 | C39: 0.1 | D39: MULTIFAMILIAR LA ABADIA 203 | E39: 1400000 | F39: 0.1 | G39: =E39*F39 -> 140000 | H39: ANDRES MIRANDA | I39: MELBI CASTRILLON | K39: 7762 | L39: BRUJAS CAMPESTRE 905 | M39: 1850000 | N39: 0.05 | O39: =N39*M39 -> 92500
B40: 7768 | C40: 0.1 | D40: BOSQUES DEL ESMERALDAL 184 | E40: 2500000 | F40: 0.05 | G40: =E40*F40 -> 125000 | H40: JUAN DIEGO HERRERA | I40: RONALD MENDEZ | K40: 7826 | L40: BIOCITY GRAND 1517 | M40: 1800000 | N40: 0.05 | O40: =N40*M40 -> 90000
B41: 7836 | C41: 0.1 | D41: MONTEPIETRA 1722 | E41: 1800000 | F41: 0.1 | G41: =E41*F41 -> 180000 | H41: ANDRES MIRANDA | I41: MELBI CASTRILLON
B42: 7816 | C42: 0.1 | D42: PUERTO LUNA 1302 | E42: 1320500 | F42: 0.1 | G42: =E42*F42 -> 132050 | H42: ANDRES MIRANDA | I42: MELBI CASTRILLON
B43: 7832 | C43: 0.1 | D43: MULTIFAMILIAR LA ABADIA 406 - 1.450.000 | E43: 1450000 | F43: 0.1 | G43: =E43*F43 -> 145000 | H43: ANDRES MIRANDA | I43: RONALD MENDEZ
B44: DESISTIDO | C44: 0.1 | D44: OCLOCK 1504 - 2700.000 | G44: =F44*E44 -> 0 | I44: MELBI CASTRILLON
...

Sheet INFORME ASESORES INTERNOS 
A3: # CONTRATO | B3: % PROPIETARIO | C3: UNIDAD | D3: OBSERVACION PORQUE CAMBIA EL % | E3: CANON | F3: % | G3: COMISION | H3: OBSERVACIONES | I3: ASESOR
A4: 7730 | B4: 0.1 | C4: MULTIFAMILIAR LA ABADIA 203 | E4: 1400000 | F4: 0.06 | G4: =E4*F4 -> 84000
A5: 7752 | B5: 0.1 | C5: CALIFORNIA 1907 | E5: 1450000 | F5: 0.06 | G5: =E5*F5 -> 87000
A6: 7762 | B6: 0.1 | C6: BRUJA CAMPESTRE 905 | E6: 1850000 | F6: 0.06 | G6: =E6*F6 -> 111000
A7: 7749 | B7: 0.1 | C7: PUERTO LUNA 813 EMPALME | E7: 1350000 | F7: 0.06 | G7: =E7*F7 -> 81000
A8: 7738 | B8: 0.1 | C8: NATIVO ARENA 1408 | E8: 2500000 | F8: 0.06 | G8: =E8*F8 -> 150000
A9: 7785 | B9: 0.1 | C9: VILLA CRISTINA 501 | E9: 1800000 | F9: 0.06 | G9: =E9*F9 -> 108000
A10: 7781 | B10: 0.1 | C10: BONANZA 301 | E10: 1800000 | F10: 0.06 | G10: =E10*F10 -> 108000
A11: 7792 | B11: 0.1 | C11: SKADARLIA | E11: 1200000 | F11: 0.06 | G11: =E11*F11 -> 72000
A12: 7813 | B12: 0.1 | C12: NATIVO MADERA 1004 | E12: 3750000 | F12: 0.06 | G12: =E12*F12 -> 225000
A13: 7836 | B13: 0.1 | C13: MONTEPIETRA 1722 | E13: 1800000 | F13: 0.06 | G13: =E13*F13 -> 108000
A14: 7816 | B14: 0.1 | C14: PUERTO LUNA 1302 | E14: 1320500 | F14: 0.06 | G14: =E14*F14 -> 79230
A15: 7834 | B15: 0.08 | C15: BRUJA BONITA 408 | E15: 2500000 | F15: 0.05 | G15: =E15*F15 -> 125000
... A18: 7854 | B18: 0.1 | C18: AMARELLO IN 1505 | E18: 1800000 | F18: 0.06 | G18: =E18*F18 -> 108000
B19: 0.1
B20: 0.1
B21: 0.1
E23: =SUM(E4:E19) -> 28220500 | G23: =SUM(G4:G18) -> 1668230
A26: INFORME INDIVIDUAL ENERO 2019- RONALD MENDEZ
A28: # CONTRATO | B28: % PROPIETARIO | C28: UNIDAD | D28: OBSERVACION PORQUE CAMBIA EL % | E28: CANON | F28: % | G28: COMISION | H28: OBSERVACIONES | I28: ASESOR
A29: 7812 | B29: 0.1 | C29: CUBIK 406 SUBROGACION | E29: 1770000 | F29: 0.02 | G29: =F29*E29 -> 35400
A30: 7782 | B30: 0.1 | C30: CHATEL 308 | E30: 2000000 | F30: 0.02 | G30: =F30*E30 -> 40000
A31: 7789 | B31: 0.1 | C31: ENTEPARQUES 623 | E31: 1850000 | F31: 0.02 | G31: =F31*E31 -> 37000
A32: 7768 | B32: 0.1 | C32: BOSQUES DEL ESMERALDAL 184 | E32: 2500000 | F32: 0.02 | G32: =F32*E32 -> 50000
A33: 7832 | B33: 0.1 | C33: MULTIFAMILIAR LA ABADIA 406 | E33: 1450000 | F33: 0.02 | G33: =F33*E33 -> 29000
A34: 7856 | B34: 0.1 | C34: BIOCITY GRAND 1517 | E34: 1800000 | F34: 0.02 | G34: =F34*E34 -> 36000
A35: 7865 | B35: 0.1 | C35: PUERTO LUNA 604 | E35: 1500000 | F35: 0.02 | G35: =F35*E35 -> 30000
B36: 0.1 | G36: =F36*E36 -> 0
B37: 0.1 | G37: =F37*E37 -> 0
B38: 0.1 | G38: =F38*E38 -> 0
E39: =SUM(E29:E35) -> 12870000 | G39: =SUM(G29:G38) -> 257400
A42: INFORME INDIVIDUAL DE ARRIENDOS ZONA ENVIGADO ENERO 2019 BIVIANA SALAZAR
A44: # CONTRATO | B44: PORCENTAJE PROPIETARIO | C44: INMUEBLE | D44: OBSERVACION CAMBIO DE % | E44: VALOR DEL CANON | F44: % | G44: COMISION
A45: 7730 | B45: 0.1 | C45: MULTIFAMILIAR LA ABADIA 203 | E45: 1400000 | F45: 0.025 | G45: =E45*F45 -> 35000
A46: 7752 | B46: 0.1 | C46: CALIFORNIA 1907 | E46: 1450000 | F46: 0.025 | G46: =E46*F46 -> 36250
A47: 7762 | B47: 0.1 | C47: BRUJA CAMPESTRE 905 | E47: 1850000 | F47: 0.025 | G47: =E47*F47 -> 46250
A48: 7749 | B48: 0.1 | C48: PUERTO LUNA 813 EMPALME | E48: 1350000 | F48: 0.025 | G48: =E48*F48 -> 33750
A49: 7738 | B49: 0.1 | C49: NATIVO ARENA 1408 | E49: 2500000 | F49: 0.025 | G49: =E49*F49 -> 62500
A50: 7785 | B50: 0.1 | C50: VILLA CRISTINA 501 | E50: 1800000 | F50: 0.025 | G50: =E50*F50 -> 45000
A51: 7781 | B51: 0.1 | C51: BONANZA 301 | E51: 1800000 | F51: 0.025 | G51: =E51*F51 -> 45000
...

Sheet INFORME ASESORES INTERNOS 2020
A1: INFORME INDIVIDUAL ENERO 2020 RONALD MENDEZ
A3: # CONTRATO | B3: % PROPIETARIO | C3: UNIDAD | D3: OBSERVACION PORQUE CAMBIA EL % | E3: CANON | F3: % | G3: COMISION | H3: OBSERVACIONES | I3: ASESOR
A5: 9286 | B5: 0.1 | C5: NATIVO FLORA 1401 2100000 | D5: ENTREGADO | E5: 2100000 | H5: FACTURADO | I5: ALEJANDRO BEDOYA
A6: 9323 | B6: 0.1 | C6: ALTOS DEL ESCOBERO 601 1´650.000 | D6: ENTREGADO | E6: 1650000 | H6: FACTURADO | I6: JUAN ESTEBAN MANRIQUE
B7: 0.09 | C7: BIOCITY 938 2´350.000 | D7: EN FIRMAS | E7: 2350000 | H7: PENDIENTE DE FACTURAR | I7: JUAN PABLO VILLA
A8: 9339 | B8: 0.1 | C8: GUALI 910 1´700.000 | D8: ENTREGADO | E8: 1700000 | H8: FACTURADO | I8: JUAN PABLO VILLA
A9: 9350 | B9: 0.1 | C9: MULTIFAMILIAR LA ABADIA 404 1´600.000 | D9: ENTREGADO | E9: 1600000 | H9: FACTURADO | I9: ANDRES MIRANDA
B10: 0.1 | C10: SALTAMONTE 426 1´900.000 | D10: EN FIRMAS | E10: 1900000 | H10: PENDIENTE DE FACTURAR | I10: ALEJANDRO BEDOYA
A11: 9344 | B11: 0.1 | C11: LAS ANTILLAS 411 1´200.000 | D11: ENTREGADO | E11: 1200000 | H11: FACTURADO | I11: ANDRES MIRANDA
A12: 9337 | B12: 0.1 | C12: VIENNA 1301 1´500.000 | D12: ENTREGADO | E12: 1500000 | H12: FACTURADO | I12: JUAN PABLO VILLA
A13: 9390 | B13: 0.1 | C13: CUMBRES DEL BOSQUE 505 1´600.000 | D13: ENTREGADO | E13: 1600000 | H13: FACTURADO | I13: JUAN PABLO VILLA
A14: 9321 | B14: 0.1 | C14: CORAZON ENVIGADO 701 900.000$ | D14: ENTREGADO | E14: 900000 | H14: FACTURADO | I14: ANDRES MIRANDA
B15: 0.1 | C15: MUGA 410 2´300.000$ | D15: EN FIRMAS | E15: 2300000 | H15: PENDIENTE DE FACTURAR | I15: ALEJANDRO BEDOYA
B16: 0.1 | C16: ALTOS DEL ESMERALDAL 705 1´800.000$ | D16: DESISTIO | H16: PENDIENTE DE FACTURAR | I16: JUAN PABLO VILLA
E17: =SUM(E5:E16) -> 18800000
A18: INFORME INDIVIDUAL ENERO 2020 DAHIANA HOYOS
A20: # CONTRATO | B20: % PROPIETARIO | C20: UNIDAD | D20: OBSERVACION PORQUE CAMBIA EL % | E20: CANON | F20: % | G20: COMISION | H20: OBSERVACIONES | I20: ASESOR
B21: 0.1 | C21: CASA INDEPENDIENTE ANDALUCIA $ 1.600.000 | D21: APROBADO BUSCANCO INMUEBLE | I21: JUAN PABLO VILLA
A22: 9328 | B22: 0.1 | C22: TORRE GUAYACAN 903 $ 2100000 | D22: ENTREGADO | E22: 2100000 | H22: FACTURADO | I22: JUAN PABLO VILLA
A23: 9291 | B23: 0 | C23: RIO SECRETO 2204 $ 1.450.000 | D23: ENTREGADO | E23: 1450000 | H23: FACTURADO | I23: ANDRES MIRANDA
A24: 9330 | B24: 0.1 | C24: MAGDALENA DE LA CUENCA 410 $ 1.350.000 | D24: ENTREGADO | E24: 1350000 | H24: FACTURADO | I24: ALEJANDRO BEDOYA
A25: 9353 | B25: 0.1 | C25: NATIVO MADERA 1704 $ 3.800.000 | D25: ENTREGADO | E25: 3800000 | H25: FACTURADO | I25: ALEJANDRO BEDOYA
A26: 9315 | B26: 0.1 | C26: MULTIFAMILIAR LA ABADIA 412 $ 1.900.000 | D26: ENTREGADO | E26: 1900000 | H26: FACTURADO | I26: JUAN PABLO VILLA
A27: 9303 | B27: 0.1 | C27: TRENTTO 411 | D27: ENTREGADO | E27: 1700000 | H27: FACTURADO | I27: ALEJANDRO BEDOYA
A28: 9349 | B28: 0.1 | C28: ST LAURENT 801 2.300.000 | D28: ENTREGADO | E28: 2300000 | H28: FACTURADO | I28: JUAN PABLO VILLA
A29: 9347 | B29: 0.1 | C29: APTO TERCER PISO ALCALA $ 1.500.000 | D29: EN FIRMAS | E29: 1500000 | H29: FACTURADO | I29: JUAN PABLO VILLA
A30: 9352 | B30: 0.1 | C30: BIOCITY 1241$ 1.700.000 | D30: ENTREGADO | E30: 1700000 | H30: FACTURADO | I30: ANDRES MIRANDA
B31: 0.1 | C31: CASA EL OASIS $ 1.100.000 | D31: DOCUEMNTOS APROBADOS /BUSCANDO APTO | I31: JUAN PABLO VILLA
B32: 0.1 | C32: BRUJA CAMPESTRE 909 $20.050.000 | D32: ENTREGADO | E32: 2050000 | I32: ALEJANDRO BEDOYA
C33: EDIFIICIO CRISTALES 202 $ 2.500.000 | D33: EN ESTUDIO | I33: JUAN ESTEBAN MARIQUE
E34: =SUM(E22:E32) -> 19850000
A35: INFORME INDIVIDUAL ENERO 2020 BIVIANA SALAZAR
A37: # CONTRATO | B37: PORCENTAJE PROPIETARIO | C37: INMUEBLE | D37: OBSERVACION CAMBIO DE % | E37: VALOR DEL CANON | F37: % | G37: COMISION
B38: 0.1 | C38: NATIVO FLORA 1401 | F38: 0.02 | G38: 2100000
E55: =SUM(E38:E54) -> 0 | G55: =SUM(G38:G54) -> 2100000
A57: INFORME INDIVIDUAL FEBRERO 2020 RONALD MENDEZ
A59: # CONTRATO | B59: % PROPIETARIO | C59: UNIDAD | D59: OBSERVACION PORQUE CAMBIA EL % | E59: CANON | F59: % | G59: COMISION | H59: OBSERVACIONES | I59: ASESOR
A61: 9286
A62: 9323
A64: 9339
...

Sheet INFORME GENERAL 2022
A1: INFORME ENERO 2022 SEDE ENVIGADO
A3: ALEJANDRO BEDOYA
A4: CAPTACIONES | B4: CONTRATO | C4: PROPIETARIO | D4: INMUEBLE | E4: CANON | F4: % | G4: comision | H4: ASESOR 2 | I4: EJECUTIVA | J4: OBSERVACIONES | K4: CONTRATO | L4: INMUEBLE | M4: CANON | N4: %
A5: 20+3 | B5: 12911 | C5: 0.1 | D5: BRUJAS CAMPESTRE 9715 2.000.000 | E5: 2000000 | F5: 0.12 | G5: =F5*E5 -> 240000 | H5: ALEJANDRO BEDOYA | I5: DARIEN CIFUENTES | K5: 13059 | L5: BALTICO 1108 | M5: 2400000 | N5: 0.05 | O5: =N5*M5 -> 120000
B6: 12921 | C6: 0.1 | D6: BIOCITY GRAND 320 2300000 | E6: 2300000 | F6: 0.12 | G6: =F6*E6 -> 276000 | H6: ALEJANDRO BEDOYA | I6: CAROLINA PARRA | K6: 13070 | L6: SENDERO FRESCO 1404 | M6: 1600000 | N6: 0.04 | O6: =N6*M6 -> 64000
B7: 12939 | C7: 0.1 | D7: ST LAURENT 602 3.900.000 | E7: 3900000 | F7: 0.12 | G7: =F7*E7 -> 468000 | H7: ALEJANDRO BEDOYA | I7: CAROLINA PARRA | K7: 13066 | L7: MUGA 1212 | M7: 2600000 | N7: 0.05 | O7: =N7*M7 -> 130000
B8: 12902 | C8: 0.1 | D8: NATIVO FLORA 1314 2.750.000 | E8: 2750000 | F8: 0.07 | G8: =F8*E8 -> 192500 | H8: PORTADA | I8: CAROLINA PARRA
B9: 12964 | C9: 0.1 | D9: FORESTA 1406 1.800.000 | E9: 1800000 | F9: 0.12 | G9: =F9*E9 -> 216000 | H9: ALEJANDRO BEDOYA | I9: CAROLINA PARRA
B10: 12835 | C10: 0.1 | D10: MUZO 1302 2.300.000 | E10: 2300000 | F10: 0.07 | G10: =F10*E10 -> 161000 | H10: MARLON RODRIGUEZ | I10: CAROLINA PARRA
B11: 13104 | C11: 0.08 | D11: AMARELLO IN 906 - 2.350.000 | E11: 2350000 | F11: 0.1 | G11: =F11*E11 -> 235000 | H11: ALEJANDRO BEDOYA | I11: CAROLINA PARRA
B12: 12965 | C12: 0.1 | D12: REGATTA 1712 - 2.600.0000 | E12: 2600000 | F12: 0.07 | G12: =F12*E12 -> 182000 | H12: JUAN DIEGO HERRERA | I12: DARIEN CIFUENTES
B13: 13093 | C13: 0.1 | D13: NATIVO ARENA 1304 - 3.300.000 | E13: 3300000 | F13: 0.07 | G13: =F13*E13 -> 231000 | H13: MARLON RODRIGUEZ | I13: CAROLINA PARRA
B14: 13080 | C14: 0.08 | D14: QUEBEC 406 - 3.800.000 | E14: 3800000 | F14: 0.1 | G14: =F14*E14 -> 380000 | H14: ALEJANDRO BEDOYA | I14: DARIEN CIFUENTES
B15: 13078 | C15: 0.1 | D15: MUGA AP 1305 - 3.100.000 | E15: 3100000 | F15: 0.12 | G15: =F15*E15 -> 372000 | H15: ALEJANDRO BEDOYA | I15: CAROLINA PARRA
B16: 12920 | C16: 0.1 | D16: FORESTA 1403 | E16: 2050000 | F16: 0.12 | G16: =F16*E16 -> 246000 | H16: ALEJANDRO BEDOYA | I16: DARIEN CIFUENTES
B19: DESISTIO | D19: TIERRA GRATA ESMERALDAL 902 - 2.500.000 | I19: CAROLINA PARRA
B20: DESISTIDO | D20: MUZO 1302 2.300.000 | I20: CAROLINA PARRA | O20: =SUM(O5:O19) -> 314000
E21: =SUM(E5:E20) -> 32250000 | G21: =SUM(G5:G20) -> 3199500 | L21: TOTAL --------------------------------------> | O21: =G21+O20 -> 3513500
A24: JUAN PABLO VILLA
A25: CAPTACIONES | B25: CONTRATO | C25: PROPIETARIO | D25: INMUEBLE | E25: CANON | F25: % | G25: comision | H25: ASESOR 2 | I25: EJECUTIVA | J25: OBSERVACIONES | K25: CONTRATO | L25: INMUEBLE | M25: CANON | N25: %
A26: 20+3
B27: 13076 | C27: 0.1 | D27: GUALI 601 1.850.000 | E27: 1850000 | F27: 0.05 | G27: =F27*E27 -> 92500 | H27: MARLON RODRIGUEZ | I27: CAROLINA PARRA
C28: 0.1 | D28: MANZANARES 1219 1.600.000 | E28: 1600000 | F28: 0.06 | G28: =F28*E28 -> 96000 | H28: PORTADA | I28: ESTEFANIA ROMERO
E31: =SUM(E27:E30) -> 3450000 | G31: =SUM(G27:G30) -> 188500 | L31: TOTAL --------------------------------------> | O31: =G31+O30 -> 188500
A33: JUAN DIEGO HERRERA
A34: CAPTACIONES | B34: CONTRATO | C34: PROPIETARIO | D34: INMUEBLE | E34: CANON | F34: % | G34: comision | H34: ASESOR 2 | I34: EJECUTIVA | J34: OBSERVACIONES | K34: CONTRATO | L34: INMUEBLE | M34: CANON | N34: %
A35: 20+3 | B35: 13015 | C35: 0.1 | D35: MANZANARES 424 1.450.000 | E35: 1450000 | F35: 0.06 | G35: =F35*E35 -> 87000 | H35: PORTADA | I35: CAROLINA PARRA | K35: 12965 | L35: REGATTA 1712 | M35: 2600000 | N35: 0.05 | O35: =N35*M35 -> 130000
B36: 13063 | C36: 0.08 | D36: CORALES DE LA ABADIA AP 1505 - 2.300.000 | E36: 2300000 | F36: 0.05 | G36: =F36*E36 -> 115000 | H36: PORTADA | I36: ESTEFANIA ROMERO | K36: 13077 | L36: REGATTA 1012 | M36: 2500000 | N36: 0.05 | O36: =N36*M36 -> 125000
B37: 13050 | C37: 0.1 | D37: EPIC 706 - 2.150.000 | E37: 2150000 | F37: 0.06 | G37: =F37*E37 -> 129000 | H37: PORTADA | I37: DARIEN CIFUENTES
B38: DESISTIO | C38: CASA BARICHARA 107 4.400.000
B39: DESISTIO | C39: NATIVO FLORA 809 3.300.000 | O39: =SUM(O35:O38) -> 255000
B40: DESISTIDO | C40: SALTAMONTE | L40: TOTAL --------------------------------------> | O40: =G41+O39 -> 586000
E41: =SUM(E35:E40) -> 5900000 | G41: =SUM(G35:G40) -> 331000
A42: MARLON RODRIGUEZ
A43: CAPTACIONES | B43: CONTRATO | C43: PROPIETARIO | D43: INMUEBLE | E43: CANON | F43: % | G43: comision | H43: ASESOR 2 | I43: EJECUTIVA | J43: OBSERVACIONES | K43: CONTRATO | L43: INMUEBLE | M43: CANON | N43: %
A44: 20+3 | B44: 12913 | C44: 0.1 | D44: ABADIA DEL CAMPO 305 1.900.000 | E44: 1900000 | F44: 0.07 | G44: =F44*E44 -> 133000 | H44: PORTADA | I44: CAROLINA PARRA | K44: 13076 | L44: GUALI 601 | M44: 1850000 | N44: 0.05 | O44: =N44*M44 -> 92500
B45: 12906 | C45: 0.1 | D45: NATIVO ARENA 1711 2.500.000 | E45: 2500000 | F45: 0.12 | G45: =F45*E45 -> 300000 | H45: MARLON RODRIGUEZ | I45: CAROLINA PARRA | K45: 13093 | L45: NATIVO ARENA 1304 | M45: 3300000 | N45: 0.05 | O45: =N45*M45 -> 165000
B46: 12929 | C46: 0.1 | D46: SAO BENTO 1404 2.250.000 | E46: 2250000 | F46: 0.07 | G46: =F46*E46 -> 157500 | H46: PORTADA | I46: CAROLINA PARRA | K46: 12835 | L46: MUZO 1302 | M46: 2300000 | N46: 0.05 | O46: =N46*M46 -> 115000
B47: 12934 | C47: 0.1 | D47: GUALI 1001 1.800.000 | E47: 1800000 | F47: 0.12 | G47: =F47*E47 -> 216000 | H47: MARLON RODRIGUEZ | I47: DARIEN CIFUENTES
B48: 12967 | C48: 0.1 | D48: GUALI 616 -1800000 | E48: 1800000 | F48: 0.12 | G48: =F48*E48 -> 216000 | H48: MARLON RODRIGUEZ | I48: DARIEN CIFUENTES
...

Sheet INFORME GLOBAL
A1: INFORME ANUAL ASESORES EXTERNOS 2022
B3: JUAN PABLO VILLA | C3: ALEJANDRO BEDOYA | D3: JUAN DIEGO HERRERA | E3: MARLON RODRIGUEZ | F3: CARLOS VALLEJO | G3: SERGIO CARMONA
A5: ENERO | B5: ='INFORME GENERAL 2022'!E31 -> 3450000 | C5: ='INFORME GENERAL 2022'!E21 -> 32250000 | D5: ='INFORME GENERAL 2022'!E41 -> 5900000 | E5: ='INFORME GENERAL 2022'!E59 -> 29400000 | G5: 0
A6: FEBRERO | B6: ='INFORME GENERAL 2022'!E225 -> 28220000 | C6: ='INFORME GENERAL 2022'!E198 -> 20150000 | D6: ='INFORME GENERAL 2022'!E238 -> 13400000 | E6: ='INFORME GENERAL 2022'!E255 -> 17300000 | G6: 0
A7: MARZO | B7: ='INFORME GENERAL 2022'!E422 -> 20004000 | C7: ='INFORME GENERAL 2022'!E402 -> 14650000 | D7: ='INFORME GENERAL 2022'!E436 -> 7580000 | E7: ='INFORME GENERAL 2022'!E460 -> 29450000 | G7: 0
A8: ABRIL | B8: ='INFORME GENERAL 2022'!E608 -> 15750000 | C8: ='INFORME GENERAL 2022'!E595 -> 6600000 | D8: ='INFORME GENERAL 2022'!E614 -> 0 | E8: ='INFORME GENERAL 2022'!E628 -> 13050000 | G8: 0
A9: MAYO | B9: ='INFORME GENERAL 2022'!E736 -> 18220000 | C9: ='INFORME GENERAL 2022'!E721 -> 23450000 | D9: ='INFORME GENERAL 2022'!E744 -> 2300000 | E9: ='INFORME GENERAL 2022'!E760 -> 21794300 | G9: 0
A10: JUNIO | B10: 16100000 | C10: 29800000 | D10: 4650000 | E10: 4200000 | G10: 0
A11: JULIO | B11: 26850000 | C11: 23800000 | D11: 0 | E11: 0 | F11: 11400000 | G11: 8500000
A12: AGOSTO | B12: 20000000 | C12: 13850000 | D12: 0 | E12: 0 | F12: 5300000 | G12: 0
A13: SEPTIEMBRE | B13: 23600000 | C13: 28350000 | D13: 0 | E13: 0 | F13: 22200000 | G13: 0
A14: OCTUBRE | B14: 20550000 | C14: 17900000 | D14: 0 | E14: 0 | F14: 24100000 | G14: 0
A15: NOVIEMBRE | B15: 20700000 | C15: 18800000 | F15: 13800000 | G15: 8400000
A16: DICIEMBRE
A18: TOTAL | B18: =SUM(B5:B17) -> 213444000 | C18: =SUM(C5:C17) -> 229600000 | D18: =SUM(D5:D17) -> 33830000 | E18: =SUM(E5:E17) -> 115194300 | F18: =SUM(F5:F17) -> 76800000 | G18: =SUM(G5:G17) -> 16900000
A19: META | B19: 192000000 | C19: 192000000 | D19: 156000000 | E19: 192000000 | F19: 192000000 | G19: 156000000
A20: DIFERENCIA | B20: =B18-B19 -> 21444000 | C20: =C18-C19 -> 37600000 | D20: =D18-D19 -> -122170000 | E20: =E18-E19 -> -76805700 | F20: =F18-F19 -> -115200000 | G20: =G18-G19 -> -139100000
A22: INFORME ANUAL ASESORES INTERNOS 2022
B24: CAROLINA PARRA | C24: ESTEFANIA ROMERO | D24: ANDREA ARISTIZABAL | E24: ESTEFHANIA VANEGAS
A26: ENERO | B26: ='INFORME GENERAL 2022'!E97 -> 31750000 | C26: ='INFORME GENERAL 2022'!E136 -> 7500000 | D26: 12000000
A27: FEBRERO | B27: ='INFORME GENERAL 2022'!E297 -> 27100000 | C27: ='INFORME GENERAL 2022'!E340 -> 25220000 | D27: 17100000
A28: MARZO | B28: ='INFORME GENERAL 2022'!E501 -> 20334000 | C28: ='INFORME GENERAL 2022'!E525 -> 25513175 | D28: 11550000
A29: ABRIL | B29: =0 -> 0 | C29: ='INFORME GENERAL 2022'!E677 -> 20800000 | D29: 13350000
A30: MAYO | B30: ='INFORME GENERAL 2022'!E796 -> 23450000 | C30: ='INFORME GENERAL 2022'!E816 -> 25220000 | D30: ='INFORME GENERAL 2022'!E835 -> 19044300
A31: JUNIO | B31: 24600000 | C31: 20600000 | D31: 13950000
A32: JULIO | B32: 27900000 | C32: 29850000 | D32: 14300000
A33: AGOSTO | B33: 23300000 | C33: 20400000 | D33: 0 | E33: 2300000
A34: SEPTIEMBRE | B34: 35000000 | C34: 37900000 | D34: 0 | E34: 12875000
A35: OCTUBRE | B35: 30450000 | C35: 30100000 | D35: 0 | E35: 6300000
A36: NOVIEMBRE | B36: 30500000 | C36: 32500000 | E36: 2300000
A37: DICIEMBRE
A39: TOTAL | B39: =SUM(B26:B37) -> 274384000 | C39: =SUM(C26:C37) -> 275603175 | D39: =SUM(D25:D38) -> 101294300 | E39: =SUM(E25:E38) -> 23775000
A40: META | B40: 216000000 | C40: 216000000 | D40: 216000000 | E40: 216000000
A41: DIFERENCIA | B41: =B39-B40 -> 58384000 | C41: =C39-C40 -> 59603175 | D41: =D39-D40 -> -114705700 | E41: =E39-E40 -> -192225000
A43: INFORME ANUAL SEDE 2022
A46: ENERO | B46: ='INFORME GENERAL 2022'!E173 -> 71000000
A47: FEBRERO | B47: ='INFORME GENERAL 2022'!E381 -> 80680000
A48: MARZO | B48: ='INFORME GENERAL 2022'!E580 -> 75247175
A49: ABRIL | B49: ='INFORME GENERAL 2022'!E698 -> 37600000
A50: MAYO | B50: ='INFORME GENERAL 2022'!E867 -> 65764300
...

Sheet CAPTACIONES 2021
A2: JUAN DIEGO HERRERA ENERO 2019
A3: FECHA | B3: TIPO | C3: UNIDAD O DIRECCION | D3: BARRIO | E3: SECTOR | F3: VALOR | G3: PORTERO O DIRECTO | H3: AVISOS | I3: FOTOS | J3: ·# | K3: EJECUTIVA
B4: APTO | C4: COLORS APTO 615 | D4: LA MINA | E4: ENVIGADO | F4: 1200000 | G4: DIRECTO | H4: SI | I4: SI | J4: 1 | K4: RONALD
B5: APTO | C5: BIOCITY 1708 | D5: ESCOBERO | E5: ENVIGADO | F5: 2700000 | G5: JHOAN | H5: SI | I5: SI | J5: 1 | K5: RONALD
B6: CASA COMERC | C6: CASA SEGUNDO PISO 34 SUR 50 | D6: ANDALUCIA | E6: ENVIGADO | F6: 2500000 | G6: DIRECTO | H6: SI | I6: SI | J6: 1 | K6: MELBI
B7: APTO | C7: NATIVO ARENA 1405 | D7: EL CHOCHO | E7: ENVIGADO | F7: 2000000 | G7: SERGIO | H7: SI | I7: SI | J7: 1 | K7: RONALD
B8: APTO | C8: BOSQUE ADENTRO 622 | D8: EL CHOCHO | E8: ENVIGADO | F8: 2400000 | G8: DIRECTO | H8: SI | I8: SI | J8: 1 | K8: RONALD
B9: APTO | C9: TURMALINA 2004 | D9: COLORES | E9: COLORES | F9: 1550000 | G9: DIRECTO | H9: SI | I9: SI | J9: 1 | K9: PORTADA
B10: APTO | C10: ATALAYA DE SAN JORGE 501 | D10: LAS BRUJAS | E10: ENVIGADO | F10: 2000000 | G10: DIRECTO | H10: NO | I10: SI | J10: 1 | K10: MELBI
B11: APTO | C11: ENTREPINOS 1906 | D11: LAS BRUJAS | E11: ENVIGADO | F11: 5500000 | G11: ADARRIAGA | H11: NO | I11: SI | J11: 1 | K11: MELBI
B12: APTO | C12: SAN JUAN DE PUEBLA 408 | D12: CUMBRES | E12: ENVIGADO | F12: 1500000 | G12: REINALDO | H12: NO | I12: SI | J12: 1 | K12: MELBI
B13: APTO | C13: SAO BENTO 1206 | D13: ESMERALDAL | E13: ENVIGADO | F13: 2400000 | G13: OSCAR | H13: NO | I13: SI | J13: 1 | K13: MELBI
B14: APTO | C14: SAO BENTO 1010 | D14: ESMERALDAL | E14: ENVIGADO | F14: 2300000 | G14: OSCAR TAPASCO | H14: NO | I14: SI | J14: 1 | K14: MELBI
B15: LOCAL | C15: LOCAL 34-30 | D15: LAURELES | E15: LAURELES | F15: 6000000 | G15: DIRECTO | H15: NO | I15: SI | J15: 1 | K15: RONALD
... B23: APTO | C23: CALIFORNIA 89 | D23: CHINGUI | E23: ENVIGADO | F23: 1500000 | G23: FAUSTO | H23: SI | I23: SI | J23: 1 | K23: MELBI
B24: APTO | C24: BIOCITY 1708 | E24: ENVIGADO | F24: 535000000 | G24: JHOAN | K24: VENTAS
B25: BODEGA | C25: BODEGA LA ALDEA | E25: GUAYABAJL | F25: 10500000000 | G25: DIRECTO | K25: VENTAS
B26: CASA | C26: JARDINES DE LA COLINA 113 | E26: ENVIGADO | F26: 1200000000 | G26: DIRECTO | K26: VENTAS
B27: APTO | C27: RESERVA DE LA MARIA 805 | E27: ENVIGADO | F27: 850000000 | G27: DIRECTO | K27: VENTAS
B28: APTO | C28: ALAMEDA 604 | E28: SABANETA | F28: 410000000 | G28: DIRECTO | K28: VENTAS
J29: =SUM(J4:J23) -> 20
A30: ALEJANDRO BEDOYA ENERO 2019
A31: FECHA | B31: TIPO | C31: UNIDAD O DIRECCION | E31: SECTOR | F31: VALOR | G31: PORTERO O DIRECTO | H31: AVISOS | I31: FOTOS | J31: ·# | K31: EJECUTIVA
B32: APTO | C32: BRUJA BONITA 1205 | D32: LAS BRUJAS | E32: ENVIGADO | F32: 2600000 | G32: RODOLFO | H32: SI | I32: SI | J32: 1 | K32: RONALD
B33: APTO | C33: BALTICO 1002 | E33: ENVIGADO | F33: 2100000 | G33: TOBINSON | H33: SI | I33: SI | J33: 1 | K33: PORTADA
B34: APTO | C34: TORRE GUAYACAN 1803 | E34: ENVIGADO | F34: 2200000 | G34: LEONARDO | H34: SI | I34: SI | J34: 1 | K34: PORTADA
B35: APTO | C35: ENTREPARQUES 1010 | E35: ENVIGADO | F35: 2050000 | G35: RAFAEL | H35: SI | I35: SI | J35: 1 | K35: PORTADA
B36: APTO | C36: MUGA 606 | E36: ENVIGADO | F36: 3000000 | G36: RAFAEL | H36: SI | I36: SI | J36: 1 | K36: PORTADA
B37: APTO | C37: HACIENDA SAN JOSE 131 | E37: ENVIGADO | F37: 4050000 | G37: DIRECTO | H37: SI | I37: SI | J37: 1 | K37: RONALD
B38: APTO | C38: CONDOMINO CUMBRES 1108 | E38: ENVIGADO | F38: 2200000 | G38: DIRECTO | H38: SI | I38: SI | J38: 1 | K38: RONALD
B39: APTO | C39: AVILA 134 | E39: ENVIGADO | F39: 8500000 | G39: DIRECTO | H39: SI | I39: SI | J39: 1 | K39: RONALD
B40: APTO | C40: BRUJAS CAMPESTRE 9716 | E40: ENVIGADO | F40: 1800000 | G40: FLOREZ | H40: SI | I40: SI | J40: 1 | K40: RONALD
B41: APTO | C41: ZURICH 1004 | E41: ENVIGADO | F41: 2250000 | G41: WEIMAR | H41: SI | I41: SI | J41: 1 | K41: MELBI
B42: APTO | C42: MUGA 902 | E42: ENVIGADO | F42: 3100000 | G42: FREDY | H42: SI | I42: SI | J42: 1 | K42: MELBI
B43: APTO | C43: BALTICO 301 | E43: ENVIGADO | F43: 1800000 | G43: TOBINSON | H43: SI | I43: SI | J43: 1 | K43: MELBI
B44: APTO | C44: PUERTO LUNA 604 | E44: ENVIGADO | F44: 1500000 | G44: JAVIER | H44: SI | I44: SI | J44: 1 | K44: MELBI
... B51: APTO | C51: PUERTO LUNA 604 | E51: ENVIGADO | F51: 1350000 | G51: JAVIER | H51: SI | I51: SI | J51: 1 | K51: PORTADA
B52: CASA | C52: AVILA 134 | E52: ENVIGADO | F52: 1350000000 | G52: DIRECTO | K52: VENTAS
B53: APTO | C53: FELISA 1001 | E53: ENVIGADO | F53: 490000000 | G53: DIRECTO | K53: VENTAS
B54: APTO | C54: MUGA 606 | E54: ENVIGADO | F54: 565000000 | G54: RAFAEL | K54: VENTAS
...

Sheet SEGUIMIENTO CLIENTES
A1: INFORME CLIENTES MES DE FEBRERO 2022
A3: JUAN PABLO VILLA | B3: CLIENTE Y QUIEN ASIGNA PORDE DONDE SALE EL CLIENTE | C3: JUAN DIEGO HERRERA | D3: CLIENTE Y QUIEN ASIGNA PORDE DONDE SALE EL CLIENTE | E3: MARLON RODRIGUEZ | F3: CLIENTE Y QUIEN ASIGNA PORDE DONDE SALE EL CLIENTE | G3: ALEJANDRO BEDOYA | H3: CLIENTE Y QUIEN ASIGNA PORDE DONDE SALE EL CLIENTE
A4: FECHA 2 DE AGOSTO DE 2021 | B4: Jorge Andres Angel Uribe - 3188884468 pregunto por casa en el esmeraldal a traves de ciencuadras B.S - El asesor sigue en seguimiento y me muestra que el cliente no define cita queda de comunicarse luego | C4: FECHA 2 DE AGOSTO DE 2021 | D4: Laura González 3003985210 - pregunto por inmueble en camino verde a traves de ciencuadras B.S indica el asesor que busca para noviembre | E4: FECHA 2 DE AGOSTO DE 2021 | F4: Nombre: luz Stella Alzate Email: luz.alzate59@gmail.com Celular: +57 3042539330 B.S | G4: FECHA 2DE AGOSTO DE 2021 | H4: consuelo bolivar p Email: fcbolivarp@gmail.com Celular: +57 3206996471 pregunta por camelot a traves de ciencuadras B.S
A5: FECHA 2 DE AGOSTO DE 2021 | B5: Hector 3006206953 pregunto por este inmueble que no esta disponible de fincaraiz | C5: FECHA 2 DE AGOSTO DE 2021 | D5: Apartamento en Arriendo - Envigado OASIS con número de referencia 6548588 en Fincaraíz.com.co y con Cod. Inmueble: 679-37917, 3227468449 en la ciudad de Manizales indica el asesor que busca para noviembre B.S | E5: FECHA 2 DE AGOSTO DE 2021 | F5: NANCY GIRALDO Email: nanchilin1228@hotmail.com Celular: +57 3213040496 pregunta por casa bosques del esmeraldal a traves de ciencuadras B.S Tambien pregunto por el otra casa de 4.000.000 | G5: FECHA 2 DE AGOSTO DE 2021 | H5: Nombre: derly castro Email: dlcastrogenetista@gmail.com Celular: +57 3204405689
A6: FECHA 2 DE AGOSTO DE 2021 | B6: MARGARITA 5817830 en Fincaraíz.com.co y con Cod. Inmueble: 679-32111,interesado en su inmueble 3156482753 Pregunto por un inmueble en zuñiga que no esta disponible | C6: FECHA 3 DE AGOSTO DE 2021 | D6: Apartaestudio en Arriendo 5843569 en Fincaraíz.com.co y con Cod. Inmueble: 679-32308, estos son los datos del cliente interesado: nombre Luisa Valentina 3127752488 LA CLIENTE PREGUNTO apto de 1.850.000 B.S | E6: FECHA 2 DE AGOSTO DE 2021 | F6: Ana Maria Picón Cabarcas Telefono : 3015034646 Correo : ana_picon20@hotmail.com pregunta por kobalto que no esta disponible B.S | G6: FECHA 2 DE AGOSTO DE 2021 | H6: Liliana Patricia Galeano Guerra Email: lipa2976@gmail.com Celular: +57 3105290272 ESTA CLEINTE YA LA VENIA ATENDIENDO ALEJANDRO Y LE HABIA MOSTRADO OPCIONES
A7: FECHA 3 DE AGOSTO DE 2021 | B7: 321 7718906 LUZ DARY CLIENTE CITA CAMINO VERDE DE LOS NARANJOS | C7: FECHA 5 DE AGOSTO 2021 | D7: CLIENTE POR LLAMADA ANGIE 3207724185 se le muestra varias opciones pero no se decide aun se le esta haciendo seguimiento CP | E7: FECHA 4 DE AGOSTO DE 2021 | F7: 3148969156- GLADYS CLIENTE VLORE Y QUEBEC, SE LE ENVIAN LAS OPCIONES, PENDIENTE DE CITA. DC | G7: FECHA 3 DE AGOSTO DE 2021 | H7: 321 4425457 VICENTE CLIENTE QUE PREGUNTA POR ZU 41 21
A8: FECHA 6 DE AGOSTO DE 2021 | B8: - Envigado CUMBRES con número de referencia 6462607 en Fincaraíz.com.co y con Cod. Inmueble: 679-37164, Ana Bero Teléfono y ciudad LLame al cliente interesado en su inmueble +5521982312610 B.S | C8: FECHA 4 DE AGOSTO DEL 2021 | D8: CLIENTE POR CORREO ANGIE 3207724185 Se le muestran varias opciones esta en seguimiento aun no se decide CP | E8: FECHA | F8: CLIENTE ISABEL 3017877109 se le muestran opciones el dia de mañana se le hace seguimiento CP | G8: FECHA 5 DE AGOSTO DEL 2021 | H8: CLIENTE POR LLAMADA ROBERTO 3014133044 se le envian opciones y se le muestra hoy aptos CP
A9: FECHA 4 DE AGOSTO 2021 | B9: cliente por correo finca raiz se le muestran varias opciones hoy YOLANDA PARRA 3008085411 C.P | C9: FECHA 6 DE AGOSTO DEL 2021 | D9: CLIENTE ANA MARIA JUVINAO LLAMADA se le va mostrar una opcion hoy segumiento CP | E9: FECHA | F9: CLIENTE FINCA RAIZ PAOLA 3007473658 Se le hace seguimiento | G9: FECHA 10 DE AGOSTO DE 2021 | H9: 3012038666 - LAURA CLIENTE ALEJANDRO MOSTRAR IBERICA VITAL CLIENTE A.B
A10: FECHA 10 DE AGOSTO DE 2021 | B10: 313 6970965 ESTEBAN CLIENTE PREGITNA POR INMUEBLE DE FINCARAIZ COLORS QUE NO ESTA DISPONIBLE SE LE BRINDA INFORMACION AL ASESOR PARA SEGUIMIENTO. BS | C10: FECHA 9 DE AGOSTO DE 2021 | D10: Cliente ximena pregunta por codigo de fincaraiz 6462374 - 3115977376 | E10: FECHA 10 DE AGOSTO EDE 2021 | F10: través de fincaraíz.com.co, un nuevo cliente se ha interesado en su inmueble Apartamento en Arriendo - Envigado LOMA BENEDICTINOS con número de referencia 5695067 en Fincaraíz.com.co y con Cod. Inmueble: 679-31254, estos son los datos del cliente interesado: nombre Mauricio vasco Teléfono y ciudad LLame al cliente interesado en su inmueble 3006184028 en la ciudad de Envigado B.S | G10: FECHA 10 DE AGOSTO DE 2021 | H10: 3154624093 - LUZ ADRIANA CLIENTE D.C MOSTRAR ESSENCE Y BRUJA BONITA
A11: FECHA 11 DE AGOSTO DE 2021 | B11: CLIENTE PREGUNTA POR CASA DE SIENA +1 (786) 260-4900 se pasa la informacion al asesor para el seguimiento. B.S | C11: FECHA 9 DE AGOSTO DE 2021 | D11: Javier Cruz [Haz click sobre el correo o el teléfono para marcar o enviar mail] +57310309721 pregunto por zarzamora, pero no esta disponible se le asigna al asesor para sweguimiento B.S | E11: FECHA 23 DE AGOSTO DE 2021 | F11: LUZ MARINA MEJIA - 3016258396 - La cliente busca apartamento en un presupuesto de 1.400.000 | G11: FECHA 11 DE AGOSTO DE 2021 | H11: 3147975098 - DIEGO CLIENTE D.C BUSCA APARTAMENTO HASTA 2.800.00 2 ALCOBAS, PEDIENTE DEL SEGUIMIENTO DEL ASESOR
A12: FECHA 11 DE AGOSTO DE 2021 | B12: 3145291513 - IMBIRA JIMENEZ CLIENTE CON PAPELES APROBADO POR 2.700.000 CLIENTE D.C "necesita $2'700.000 2'500.000 en las brujas" | C12: FECHA 12 DE AGOSTO DE 2021 | D12: Nombre: Camila avila Email: camilaavila_9702@hotmail.com Celular: 3012333799 | E12: FECHA 23 DE AGOSTO DE 2021 | F12: EVELYN RINCON . 3223206434 - Le gusto sauces de la concha, aun no se agenda visita al apto | G12: FECHA 23 DE AGOSTO DE 2021 | H12: LUIS FERNANDO RESTREPO - 3146798546 - el cliente busca apartamento amplio en un presupesto de 2.300.000, el asesor le envía opciones
A13: FECHA | B13: Nombre: paula vasquez Email: vpaula_alejandra@hotmail.com Celular: +57 3005999373 cliente de Ciencuadras B.S | C13: FECHA 13 DE AGOSTO DE 2021 | D13: ANDREA MONTOYA - 3192540331 MOSTRAR LA CUENCA, CLIENTE D.C | E13: FECHA 24 DE AGOSTO DE 2021 | F13: HUMAR - 3057538309 - el cliente tiene un presupuesto de 1.500.000 busca apartamento de 3 alcobas | G13: FECHA 23 DE AGOSTO DE 2021 | H13: GIRBERTO - 3127797137 - al señor le gusto tramontana, aun no se agenda la cita, el asesor le envía las opciones disponibles
A14: FECHA 23 DE AGOSTO DE 2021 | B14: Jesica - 3207148868 La cliente pregunto por Kobalto, tiene un presupuesto de 1.600.000, el asesor aun no ha agendado cita. 27/08/2021 Se le enviaron opciones y no respondío, reviso el chat y no informó para programar cita | C14: FECHA 18 DE AGOSTO DE 2021 | D14: A través de fincaraíz.com.co, un nuevo cliente se ha interesado en su inmueble Apartamento en Arriendo - Envigado EL PORTAL con número de referencia 6509996 en Fincaraíz.com.co y con Cod. Inmueble: 679-29569, estos son los datos del cliente interesado: nombre Karen Teléfono y ciudad LLame al cliente interesado en su inmueble 3016516503 en la ciudad de Medellin | E14: FECHA 24 DE AGOSTO DE 2021 | F14: RAUL BARRIOS - 3106181525 - El señor busca apartamento de dos alcobas, en el sector de la forntera | G14: FECHA 23 DE AGOSTO DE 2021 | H14: LAURA ALZATE - 3136249399 - La cliente buasca un apartamento de 3 alcobas con un presupuesto de 3 millones, el asesor le envía opciones.
... A16: FECHA 23 DE AGOSTO DE 2021 | B16: GUSTAVO RENDON - 3104443584 - Se agenda cita para el miercoles a las 12 en el Porton Del Dorado, Le gusto el apartamento, lo quiere volver a ver el dia sabado 28 de agosto. | C16: FECHA 18 DE AGOSTO DE 2021 | D16: inmueble de 1.650.000 pero no esta disponible William Pabon +573116055941 | E16: FECHA 24 DE AGOSTO DE 2021 | F16: 3013784768 alexander se le hace seguimiento busca hasta 1.500 | G16: FECHA 26 DE AGOSTO DEL 2021 | H16: laura 301 3198532 quiere apto de 3 alcobas le gusta oclock se le hace seguimiento
A17: FECHA 23 DE AGOSTO DE 2021 | B17: LINA MOLINA - 3183890875 - la cliente es una reubicación, esta pendiente a entregar un apartamento que tiene con nosotros, 27/08/2021 se le enviara la opcion de Milan, ya que busca apartamento en parte baja, busca una unidad más nueva, el presupuesto es de 1.600.000 | C17: FECHA 18 DE AGOSTO DE 2021 | D17: Apartamento en Arriendo - Envigado LOMA DE LAS BRUJAS con número de referencia 6513438 en Fincaraíz.com.co y con Cod. Inmueble: 679-37576, estos son los datos del cliente interesado: nombre Diana Jiménez Teléfono y ciudad LLame al cliente interesado en su inmueble +573006629228 en la ciudad de Medellín | E17: FECHA | G17: FECHA 6 DE SEPTIEMBRE | H17: 313 6216006 maria gomez CLIENTE INTERNA busca casa hasta 4 millones se le hace seguimiento CP
A18: FECHA 23 DE AGOSTO DE 2021 | B18: MARGARITA ARIAS - 3127889553 - La cliente busca apartamnto amplio, en un presupuesto de 4.500.000. 27/08/2021 la señora busca apartamento en Poblado, se le paso el dato a un compañero de la sede. | C18: FECHA 23 DE AGOSTO DE 2021 | D18: KEREN - 3046361235 - La cliente agendo una cita para ver Manzanares, estamos pendientes de enviarle mas opciones. | E18: FECHA | G18: FECHA
A19: FECHA 24 DE AGOSTO DE 2021 | B19: JUAN DIEGO RAMIREZ - 3212416874 - Se le asigna cita para el 25, en la tarde el cliente confirma que no puede acomodar el horario con el horario en que lo muestra la propietaria. 20/08/2021 pendiente de cita el sabado 28 en bruja bonita. | C19: FECHA 23 DE AGOSTO DE 2021 | D19: LUIS ESTEBAN - 3183587999 - busca apartamento de 70 mts, de tres alcobas en 1.500.000 se le envían opciones. | E19: FECHA | G19: FECHA
A20: FECHA 24 DE AGOSTO DE 2021 | B20: YULIETH VIEIRA - 3505997398 - La cliente busca apartamento amplio en un presupuesto de 3.700.000, el asesor le brinda la información. 27/082021 se le envío todo lo que había disponible, no le gusto ninguna. | C20: FECHA 23 DE AGOSTO DE 2021 | D20: VALLERY - 3187122168 - busca apartamento de tres alcobas en un presupuesto de 1.700 el asesor se encarga de enviarle las opciones. | E20: FECHA | G20: FECHA
A21: FECHA 24 DE AGOSTO DE 2021 | B21: NATASCHA 3006742424 VA TOMAR EL APTO DE ZEBRANO SE LE MOSTRO AYER CP | C21: FECHA 24 DE AGOSTO DE 2021 | D21: ANA - 3046534146 - Busca opciones en el sector de la cuenca o cumbres, el asesor le envía opciones " le mostré manzanares 718 pero q no le sirven de ese metraje por q tiene sala muy grande le ofrecí Zurich y q ya lo había visto, tiene maximo 2.000.000" | E21: FECHA | G21: FECHA
A22: FECHA 10 DE AGOSTO DE 2021 | B22: OLGA 319 3771281 se le muestra en el sector de la cuenca se le hace seguimineto | C22: FECHA 24 DE AGOSTO DE 2021 | D22: DUNELLA MAYA - 3147077247 - busca apartamento de tres alcobas con 3 baños - 26/08/2021 la cliente quiero si o si en Ceylan 34 en poblado. | E22: FECHA | G22: FECHA
A23: FECHA | C23: FECHA 24 DE AGOSTO DE 2021 | D23: ANDREA PEREZ - 3105103665 - Busca apartamento en el sector de la paz - 26/08/2021 ya le mostré la cuenca pero no le gusto la vista de manzanares por el ruido y le mandé Zurich. | E23: FECHA | G23: FECHA
A24: FECHA | C24: FECHA 23 DE AGOSTO DE 2021 | D24: GLORIA DURAN - 3044532188 - busca apartamento en cumbres. Se le envio refugio verde, pendiente de agendar visita. | E24: FECHA | G24: FECHA
A25: FECHA | C25: FECHA 25 DE AGOSTO DE 2021 | D25: DIANA ROMERO - 3207642007 - Se agenda cita para el 26, mostrar el 1207 de Zurich "le gustó Zurich pero q quiere ver más opciones por allá ya le dije q papelería debe presentar" | E25: FECHA | G25: FECHA
A26: FECHA | C26: FECHA 25 DE AGOSTO DE 2021 | D26: carlos 317 8746139 se le muestra opciones esta en segumiento | E26: FECHA | G26: FECHA
A27: FECHA | C27: FECHA 26 DE AGOSTO DE 2021 | D27: Juan Felipe Velasquez - 301 2011090 - el cliente pregunto por Tramontana, el asesor le envia mas opciones - " estoy mirando q ofrecer tiene varios pedidos pero q no tiene afán q puede esperar hasta 4 meses pero ya le estoy buscando tiene máximo 1800 cerca a la frontera" | E27: FECHA
C28: FECHA 15 DE AGOSTO DEL 2021 | D28: andrea escobar 3136145850 cliente se le envian varias opciones pero no se sube de presupuesto CP | E28: FECHA
C29: FECHA 20 DE AGOSTO DEL 2021 | D29: ANA MARIA 3188218156 se le muestran opciones pero no concreto aun se le hace seguimiento porque no se a ubicado CP
C30: FECHA 10 DE AGOSTO DEL 2021 | D30: ANGIE 3207724185 cliente pendiente se le han mostrado opcones sigue en seguimiento CP
C31: FECHA 19 DE AGOSTO DEL 2021 | D31: DIANA 300 2546460 se le envian opciones pendiente de que indique ue quiere ver se lehace seguimiento CP
A33: INFORME CLIENTES MES DE SEPTIEMBRE 2021
A35: JUAN PABLO VILLA | B35: CLIENTE Y QUIEN ASIGNA PORDE DONDE SALE EL CLIENTE | C35: JUAN DIEGO HERRERA | D35: CLIENTE Y QUIEN ASIGNA PORDE DONDE SALE EL CLIENTE | E35: MARLON RODRIGUEZ | F35: CLIENTE Y QUIEN ASIGNA PORDE DONDE SALE EL CLIENTE | G35: ALEJANDRO BEDOYA | H35: CLIENTE Y QUIEN ASIGNA PORDE DONDE SALE EL CLIENTE
A36: 27 DE AGOSTO DEL 2021 | B36: NATASCHA 3006742424 CLIENTE SE LE OFRECE ZEBRANO Y LO VA TOMAR | C36: 30 DE AGOSTO DEL 2O21 | D36: ANA MARIA NUMERO EXTRANJERO SE LE HACE SEGUIMIENTO CLIENTE ASIGNO INTERNA | E36: 29 DE AGOSTO DEL 2021 | F36: LUZ 3127907139 CLIENTE hasta 1.800 se le ofrece una opcion pero no le gusta se le hace seguimiento cliente ASESOR INTERNO | G36: FECHA:30 AGOSTO | H36: CLIENTE POR CHAT SEÑORA JANET, PREGUNTO POR APTO EN QUEBEC 3002010948 - B.S
A37: FECHA: 30 AGOSTO | B37: JUAN DIEGO 3118695628 CLIENTE ASESOR, se programa para mostrar foretti 1402 y 1402, cancela la cita, pendiente volver a programar, X | C37: 31 DE AGOSTO DEL 2021 | D37: yolanda 3113415063 ella busca 2 a 3 alcobas hasta 2.500 se le hace seguimiento cliente ASESOR INTERNO CP | E37: FECHA: 30 AGOSTO | F37: DIANA 3054641532 CLIENTE LLEGO A LA OFICINA, se le muestra sonata 506, sao bento 312, faro del esmeraldal 712, trento 308, CLIENTE PASA DOCUMENTOS PARA SONATA SI | G37: FECHA:30 AGOSTO | H37: SEBASTIAN 319 7285493, CLIENTE ASESOR, se le va a mostrar Cubik APROBADO PARA ARRIENDO FECHA INICIO 24/09/21 X
A38: FECHA: 31 AGOSTO | B38: LINA JIMENEZ 3174009696 CLIENTE INTERNA, se le ofrece epic 502, sonata 506, santorini 704, 4 SEP le va a mostrar epic, klaus y sao bento, AUN NO DEFINE, SE PASA DOCUMENTOS POR TIERRA GRATA ESMERALDAL 912 SI | C38: FECHA: 2 DE SEPTIEMBRE | D38: LAURA 3134770606 CLIENTE ASESOR, mostrar Verdum X | E38: FECHA: 30 AGOSTO | F38: JULIANA RESTREPO 3234815169, CLIENTE ASESOR se le muestra faro del esmeraldal X | G38: FECHA: 30 AGOSTO | H38: JUAN PABLO JIMENEZ 3206998148 CLIENTE ASESOR, se le va a mostrar nativo arena 1616 PASA DOCUMENTOS PARA RADICAR 01/09/21. DOCUMENTOS APROBADOS SE ENTREGA A INQUILINA 07 SEPTIEMBRE SI
A39: FECHA: 31 AGOSTO | B39: ALEXANDRA GARCIA 3017817099, CLIENTE ASESOR, se le va a mostrar zurich 1207, cancela la cita pendiente volver a confirmar, SE PROGRAMA PARA EL 2 SEP MOSTRAR CASTELLI Y ZURICH, PASA DOCUMENTOS PARA RADICAR 6 SEP, DOCUMENTOS APLZADOS SI | C39: FECHA 3 DE SEPTIEMBRE DEL 2021 | D39: FRANCISCO 301 4975728 CLIENTE INTERNA se le informa de dos opciones se le hace seguimiento | E39: FECHA: 31 AGOSTO DEL 2021 | F39: CAMILO 3146547302 ASESOR INTERNA se le hace seguimiento pendiente de enviar oociones | G39: FECHA : 30 AGOSTO 2021 | H39: yanet 3002010948 busca apto hasta 3.200 se le hace segumiento cliente ASESOR INTERNA CP
A40: FECHA: 31 AGOSTO | B40: CAMILA 3233828709 cliente ASESOR INTERNA se le hace seguimiento busca de 3 alcobas | C40: 3 DE SEPTIEMBRE DEL 2021 | D40: ASRTID 301 5061758 CLIENTE INTERNA se le ofrece trentto tiene cita mañana 10 am CP | E40: FECHA: 31 AGOSTO | F40: GLADYS 316832599 CLIENTE ASESOR, mostrar casa cumbres, cliente se ubico con otra inmobiliaria X | G40: FECHA: 31 AGOSTO | H40: JOSHUA 3012147726 CLIENTE INTERNA, se le va a mostrar quebec 1209 Y Firenzze 805, 2 sep inquilino se acomodo con otra inmobiliaria X
A41: FECHA: 01 SEPTIEMBRE | B41: NATALIA 3206728110 CLIENTE ASESOR, mostrar manzanares de la cuenca 418 X | C41: FECHA: 6 DE SEPTIEMBRE | D41: CAROL BEJARANO 319 3450124, CLIENTE INTERNA, mostrar locales de los naranjos y santorino, no le gustaron X | E41: FECHA 3 SEPTIEMBRE | F41: 311 3700078 JUAN CLIENTE ASESOR INTERNA SE LE HACE SEGUIMIENTO CP | G41: FECHA: 31 AGOSTO | H41: JORGE ALIRIO 3216432351 CLIENTE ASESOR, mostrar edificio la matina, SE PIDE TRASLADO EL 02 SEPT APROBADOS SI
A42: FECHA: 02 SEPTIEMBRE | B42: GERMAN SANTACOLOMA 3118413834, CLIENTE INTERNA, mostrar venetto 303 y muratto X | C42: FECHA: 7 DE SEPTIEMBRE | D42: JOSE 316 8314374 CLIENTE INTERNA, mostrar trentto 308, PASA DOCUMENTOS POR CDT SI | E42: FECHA: 7 DE SEPTIEMBRE | F42: JHOANA 319 4745223 CLIENTE INTERNA, mostrar casa 146 de villa real, no se ha decidido X | G42: FECHA: 31 AGOSTO DEL 2021 | H42: VALENTINA SOTO 301 3198532 CLIENTE ASESORA INTERNA se le envia opciones y va ver nativo arena se le hace seguimiento CP
A43: FECHA 2 DE SEPTIEMBRE | B43: sandeep 311 3507305 le mando epic 502 y busca hasta 2 millones CLIENTE INTERNA | C43: FECHA 9 DE SEPTIEMBRE | D43: 3126341681 dario barrera SE LE HACE SEGUIMIENTO CLIENTE INTERNA CP | E43: FECHA 8 DE SEPTIEMBRE | F43: martha serrano 3014553364 CLIENTE INTERNA se le hace seguimiento busca apto hasta 3 millones CP | G43: FECHA 2 SEPTIEMBRE | H43: SANDRA 310 8410833 CLIENTE INTERNA se le muesta nogales pero pide rebaja se le hace seguimiento
A44: FECHA: 4 SEPTIEMBRE | B44: ANGELA 3148898222 CLIENTE ASESOR, le va a mostrar epic 502 y 507, y trentto APROBADOS PARA EPIC 507 X | C44: FECHA 20 SEPTIEMBRE | D44: MAURICIO CLIENTE INTERNA, MOSTRAR CUBIK 910. ESTA RADICANDO SI | E44: FECHA: 11 DE SEPTIEMBRE | F44: CRISTIAN 3008025559 CLIENTE ASESOR, mostrar casa 146 villa real, pasa propuesta por 2.100 X | G44: FECHA 6 DE SEPTIEMBRE DEL 2021 | H44: 313 6216006 maria gomez CLIENTE INTERNA busca casa hasta 4 millones se le hace seguimiento CP
...

Sheet INFORME GENERAL 2021
A1: INFORME ENERO 2021 SEDE ENVIGADO | P1: 45
A3: ALEJANDRO BEDOYA
A4: CONSIGNACIONES | B4: CONTRATO | C4: PROPIETARIO | D4: INMUEBLE | E4: CANON | F4: % | G4: comision | H4: ASESOR 2 | I4: EJECUTIVA | J4: OBSERVACIONES | K4: CONTRATO | L4: INMUEBLE | M4: CANON | N4: %
B5: 10465 | C5: 0.1 | D5: IBERICA 701 $ 1.700.000 | E5: 1700000 | F5: 0.07 | G5: =E5*F5 -> 119000 | H5: PORTADA | I5: CAROLINA PARRA
B6: 10493 | C6: 0.1 | D6: EPIC 706 - 1.950.000 | E6: 1950000 | F6: 0.12 | G6: =E6*F6 -> 234000 | H6: ALEJANDRO BEDOYA | I6: CAROLINA PARRA
A7: 20+10 | B7: 10489 | C7: 0.1 | D7: NATIVO FLORA 616 2.400.000 | E7: 2400000 | F7: 0.12 | G7: =E7*F7 -> 288000 | H7: ALEJANDRO BEDOYA | I7: CAROLINA PARRA
B8: 10508 | C8: 0.1 | D8: LA RESERVA 701 2.800.000 | E8: 2800000 | F8: 0.07 | G8: =E8*F8 -> 196000 | H8: PORTADA | I8: BIVIANA SALAZAR
B9: 10576 | C9: 0.1 | D9: BIOCITY GRAND 804 - 1.700.000 | E9: 1700000 | F9: 0.07 | G9: =E9*F9 -> 119000 | H9: PORTADA | I9: CAROLINA PARRA
B10: FIRMAS | D10: LYON 2.200.000 | I10: LUISA MARIN
B11: DESISTIDO | D11: LUZ VIRGINIA PEREZ ALZATE 63278353 $ 1.500.000 | I11: DAHIANA HOYOS
B12: DESISTIDO | D12: SAN JUAN DE LAS ORQUIDEAS 704 $ 2550000 | I12: DAHIANA HOYOS
D13: BENEDICTINE GARDEN 1603 $ 4.800.000 | I13: DAHIANA HOYOS
B14: DESISTIDO | D14: REGATTA 708 - 2-300.000 | I14: CAROLINA PARRA
B15: DESISTIDO | D15: QUEBEC 1102 2.400.000 | I15: CAROLINA PARRA
B16: DESISTIDO | D16: CUBIK 910 SUBROGACION 2.300.000 | I16: BIVIANA SALAZAR | O16: =SUM(O9:O15) -> 0
D17: TOTAL | E17: =SUM(E5:E16) -> 10550000 | F17: TOTAL | G17: =SUM(G5:G16) -> 956000 | L17: TOTAL--------------------------------------> | O17: =O16+G17 -> 956000
A19: JUAN PABLO VILLA
A20: CONSIGNACIONES | B20: CONTRATO | C20: PROPIETARIO | D20: INMUEBLE | E20: CANON | F20: % | G20: comision | H20: ASESOR 2 | I20: EJECUTIVA | J20: OBSERVACIONES | K20: CONTRATO | L20: INMUEBLE | M20: CANON | N20: %
A21: 26+10 | B21: 10496 | C21: 0.1 | D21: PUERTO LUNA 510 | E21: 1450000 | F21: 0.12 | G21: =E21*F21 -> 174000 | H21: JUAN PABLO VILLA | I21: DAHIANA HOYOS
B22: 10515 | C22: 0.1 | D22: PUERTO LUNA 1502 | E22: 1500000 | F22: 0.12 | G22: =E22*F22 -> 180000 | H22: JUAN PABLO VILLA | I22: CAROLINA PARRA
B23: 10579 | C23: 0.1 | D23: MISSISSIPPI DE LA CUENCA 1310 | E23: 1400000 | F23: 0.12 | G23: =E23*F23 -> 168000 | H23: JUAN PABLO VILLA | I23: CAROLINA PARRA
B24: 10517 | C24: 0.1 | D24: GUADALCANAL 150 $ 2.200.000 | E24: 2200000 | F24: 0.12 | G24: =E24*F24 -> 264000 | H24: JUAN PABLO VILLA | I24: DAHIANA HOYOS
B25: 10542 | C25: 0.1 | D25: CASTELLI 1109 - 1750000 | E25: 1750000 | F25: 0.07 | G25: =E25*F25 -> 122500 | H25: SEBASTIAN MONTOYA | I25: DAHIANA HOYOS
B26: 10509 | C26: 0.08 | D26: NUEVA ORQUIDEA 504 | E26: 2200000 | F26: 0.1 | G26: =E26*F26 -> 220000 | H26: JUAN PABLO VILLA | I26: DAHIANA HOYOS
B27: 10490 | C27: 0.1 | D27: PUNTA DEL PARQUE 601 | E27: 3200000 | F27: 0.12 | G27: =E27*F27 -> 384000 | H27: JUAN PABLO VILLA | I27: DAHIANA HOYOS
B28: 10564 | C28: 0.1 | D28: ATALAYA DE SAN JORGE 1101 - 2.000.000 | E28: 2000000 | F28: 0.07 | G28: =E28*F28 -> 140000 | H28: PORTADA | I28: LUISA MARIN
B29: 10563 | C29: 0.1 | D29: ATALAYA DE SAN JORGE 1308 - 2.000.000 | E29: 2000000 | F29: 0.07 | G29: =E29*F29 -> 140000 | H29: PORTADA | I29: CAROLINA PARRA
B30: DESISTIDO | D30: ZURICH 406 $ 1550.000 EN BUSCA DE APTO | I30: DAHIANA HOYOS
B31: DESISTIDO | D31: CORALES DE LA ABADIA 501 - 1.800.000 | I31: DAHIANA HOYOS
B32: DESISTIDO | D32: BIOCITY 804 1.700.000 | I32: CAROLINA PARRA
B33: PENDIENTES | D33: RECINTOS DE LA ABADIA 1504 -EN ESTUDIO LIBERTADOR | I33: DAHIANA HOYOS
D34: MISSISSIPPI 1310 1.400.000 | I34: CAROLINA PARRA
B35: DESISTIDO | D35: CASA LAS BRUJAS 3.000.000 | I35: DAHIANA HOYOS
O38: =SUM(O21:O27) -> 0
D39: TOTAL | E39: =SUM(E21:E37) -> 17700000 | F39: TOTAL | G39: =SUM(G21:G38) -> 1792500 | L39: TOTAL--------------------------------------> | O39: =O38+G39 -> 1792500
A42: SEBASTIAN MONTOYA
A43: CONSIGNACIONES | B43: CONTRATO | C43: PROPIETARIO | D43: INMUEBLE | E43: CANON | F43: % | G43: comision | H43: ASESOR 2 | I43: EJECUTIVA | J43: OBSERVACIONES | K43: CONTRATO | L43: INMUEBLE | M43: CANON | N43: %
A44: 11+1 | L44: CASTELLI 1109 - 1750000 | M44: 1750000 | N44: 0.04 | O44: =M44*N44 -> 70000
B45: 10536 | D45: SANTA TERESITA 302 1.300.000 | E45: 1300000 | F45: 0.08 | G45: =E45*F45 -> 104000 | H45: SEBASTIAN MONTOYA | I45: CAROLINA PARRA
B46: 10532 | D46: BIOCITY GRAN 1142 - 2.200.000 | E46: 2200000 | F46: 0.04 | G46: =E46*F46 -> 88000 | H46: ALEJANDRO OCAMPO | I46: LUISA MARIN
...

Sheet LLAVES 
A1: INVENTARIO LLEVES SEDE
A2: NUMERO | B2: NOMBRE DE LA UNIDAD | C2: INMUEBLE | D2: OBSERVACIONES
A3: 1
A4: 2
A5: 3
A6: 4
A7: 5
A8: 6
A9: 7
A10: 8 | B10: LOCAL TRIANON 39 B 04
A11: 9
A12: 10
A13: 11
A14: 12 | B14: VILLANUEVA DE LA AYURA | C14: 1105
A15: 13
A16: 14
A17: 15
A18: 16 | B18: CORALES DE LA ABADIA | C18: 1105
A19: 17
A20: 18
A21: 19 | B21: PORTON DEL DORADO | C21: 103
A22: 20
A23: 21
A24: 22 | B24: PALMERAS | C24: 708
A25: 23
A26: 24
A27: 25 | B27: REGATTA AP 613
A28: 26 | B28: VERGEL SEÑIOR CLUB | C28: 336
A29: 27
A30: 28
A31: 29 | B31: LOCAL MESA 38 SUR 36 | C31: 401
A32: 30 | B32: LOCAL PORTAL DEL CERRO | C32: 161 | D32: 1350000
A33: 31 | B33: LOCAL SAN MARCOS 32 B 27
A34: 32 | B34: LOCAL ANDA LUCIA | D34: 1200000
A35: 33
A36: 34
A37: 35
A38: 36 | B38: MISSISSIPPI 1111
A39: 37 | B39: CASTELLI 1210 | C39: 1210 | D39: 1900000
A40: 38 | B40: BIOCITY GRAND | C40: 435 | D40: 2400000
...

Sheet PORTERIAS ENVIGADO
A2: SECTOR | B2: UNIDAD | C2: PORTERO | D2: NUMERO | E2: DIRECCION | F2: NUMERO DE ADMINISTRACION | G2: HORARIO DE TRATEOS Y DEPOSITOS
A3: ABADIA | B3: ABADIA DEL CAMPO | C3: EVER HIGUITA | D3: 3211126 | E3: Calle 25 Sur 41-35 | G3: Lunes a Viernes de 8 - 12 y 2-5 Sábado (pendiente) - Deposito$ 150.000
A4: FRONTERA ZÚÑIGA | B4: ACANTO | C4: JORGE LEON LOPEZ | D4: 3136419 - 3117976586 | E4: Carrera 41A#22 Sur 87 | G4: Lunes a viernes de 8 -12 2-5 100.000
A5: SEÑORIAL | B5: AGUA DULCE | C5: CARLOS OLIVEROS-ARLEY | D5: 5963927 - 3122624757 | E5: Calle 46D Sur 42D-80 | G5: Lunes a Viernes de 8:30 a 5:00 pm Sábado 8:30 a 2:00 - Deposito $150.000
A6: SEÑORIAL | B6: AIRE DEL BOSQUE | C6: ALBERTO GIRALDO | D6: 3348418 | E6: CALLE 48 C SUR 42A-80 | G6: Lunes a Viernes de 8:00 a 5:00 pm Sábado 9:00 a 5:00 - No tiene deposito
A7: LA COLA DEL ZORRO | B7: ALCARAVAN | C7: HUMBERTO NAVARRO | D7: 3116121 | E7: Carrera 25A#10-75
B8: ALMENDROS DE ZUÑIGA | C8: RUBEN TUBERQUIA | D8: 5781764 | E8: CALLE 20 SUR 45 - 107
A9: SEÑORIAL | B9: ALTOS DE LOS ALMENDROS | C9: ANDRES | D9: 3504731400 - 2092936 | G9: LUNES A VIERNES DE 8 AM - 5 PM SABADO DE 8 AM - 1 PM NO DEPOSITO
A10: LAS FLORES | B10: ALTOS DE MAYORCA | D10: 5962197 | E10: CALLE 52 SUR 43 A - 57
A11: SEBASTIANA | B11: ALTOS DEL CLARAVAL | C11: CESAR GALLO | D11: 3360217 | E11: CALLE 36 SUR 25 - 153
A12: ESCOBERO | B12: ALTOS DEL ESCOBERO | D12: 3362471 | E12: Carrera 27A#37 Sur 07 | F12: 3362471 DIANA | G12: LUNES A VIERNES 8AM- 5PM Y SABADO DE 8AM - 2PM DEPOSITO $300.000
A13: INTERMEDIA | B13: AQUAMONTE | C13: CARLOS RODRIGUEZ | D13: 3344810 | E13: CALLE 36 AA SUR 26 A - 30 | G13: Lunes a Viernes de 8:00 a 4:00 pm Sábado 8:00 a 12:00 - No tiene deposito
A14: LA MINA | B14: COLORS | C14: JAVIER CASTILLO | D14: 5577709 | E14: CARRERA 24 DDNo. 41 SUR 190 | F14: BEATRIZ - 3176710977 | G14: Lunes a Viernes de 8:30 a 5:00pm sabados de 9:00 am a 3:00 pm no deposito
A15: LOMA DE LAS BRUJAS | B15: CUBIK | C15: CARLOS MARTINEZ | D15: 3144372301 | E15: CALLE 37 B SUR 27 D - 84 | F15: ADMON 4442420- 5788010 | G15: LUNES A VIERNES 8:00 A 4:00 PM SABADOS 8:00 A 12:00 DEPOSITO 200.000
B17: ALTO DEL ESMERALDAL | C17: MAURICIO | D17: 3662572 | E17: Calle 27 Sur 27-80
A18: LA FRONTERA | B18: B | E18: Carrera 15#9A-23
A19: LAS BRUJAS | B19: ATALAYA DE SAN JORGE | C19: luis garaby | D19: 5707547 | E19: CALLE 37 B SUR 27 B - 81 | G19: LUNES A VIERNES 8:30 5:00 SABADOS 8:00 A 2:00 PM DEPOSITO 150000
A20: EL ESMERALDAL | B20: AMARELLO IN | D20: 3566116 | E20: A | F20: ADMON 3135679 - 5804034 | G20: Lunes a Viernes 8am-5pm jornada continua y sabados 8:30am-1:30pm, deposito 200000
A21: ANTILLAS | B21: ANTILLAS 1 | C21: LUIS VALENCIA | D21: 3348156 | E21: CARRERA 36D 43 SUR-100
A22: ANTILLAS | B22: ANTILLAS 3 | C22: HAMILSON MONTOYA | E22: CARRERA 36 D 42 SUR - 50
A23: INTERMEDIA | B23: AQUAMONTE | C23: CARLOS RODRIGUEZ | D23: 3344810 | E23: CALLE 36AA SUR 26A 30
B24: ARBOLEDA DE CUMBRES | C24: LUIS CARLOS GOMEZ | D24: 3363891 | E24: CARRERA 27B 27D SUR 81
A25: CAMINO VERDE | B25: ARBOLEDA DE LAS BRUJAS | C25: JORGE URREGO-CARLOS | E25: CARRERA 29 A 39 SUR - 34 | F25: 3187641071 - magdalena guzman 5406350 opc 1 | G25: lunes a viernes de 8: 400 pm sabados 8:00 a 12:00
B26: ARBOLEDA DEL ESMERALDAL | C26: EDGAR MURIEL | D26: 5795374 | E26: CALLE 27 SUR 27 D - 79 | G26: lunes a viernes de 8: 400 pm sabados 8:00 a 12:00 DEPOSITO $ 100.000
B27: AREKA | C27: ELKIN TABORDA | D27: 5994433 - 3162062530 | E27: CALLE 27 SUR 27B-87 | G27: LUNES A VIERNES DE 8 AM - 4 PM Y SÁBADO DE 8 AM - 2 PM DEPOSITO $ 300.000
B28: AMARETTO
A29: ABADIA | B29: ARRECIFES DE LA ABADIA | C29: PORTERIA | D29: 3232205779 Y 5454161 | E29: Calle 27D Sur 28-50
B30: ROCIO DE LA MAÑANA | C30: RAUL ESCOBAR | D30: 3212575 | E30: Calle 27 Sur 28 | F30: L-V 8 AM - 3 PM SABADO 8 1 PM
B31: AUSTRAL | D31: 5776700 | E31: CALLE 36 SUR 27 A - 24
B32: BALCONES DE LA RAZA | C32: REINALDO | D32: 5978576 - 3106360409 | E32: CALLE 48C SUR 39A 165
B33: BALCONES DE TIERRA LINDA | C33: NICOLAS BEDOYAS | D33: 5776762 | E33: CARRERA 27A 36 D SUR 201
B34: BIOCITY EPIC | D34: 5577426 | E34: 3127814349 administracion | G34: LUNES A VIERNES DE 8AM A 5 PM - SABADOS DE 8AM A 2PM
D35: 4797922 | E35: Administración 3103891390 gloria bedoya | F35: 3019546 -5783987 KATERINE FACTURACIN ADMON | G35: lunes a viernes 8 am - 5 pm y sabado 10 am a 2 pm deposito 100.000 apartar la mudanza 1dia antes
B36: BALCONES DEL SUR | C36: JUAN SERNA | D36: 5978152 | E36: CALLE 49D SUR 40A 469
B37: BALTICO | C37: ANDRES RAMOS | D37: 5577514 | E37: Carrera 27#36 Sur 159 | G37: lunes viernes 8-12 y 2 - 6 sabados 8 - 2 deposito 250000
B38: BARICHARA | C38: FABER MUÑOZ | D38: 3669387 | E38: CARRERA 20 25 SUR 81 | G38: 0
A39: BENEDICTINOS | B39: BENEDICTINE PARK | C39: ODIVER RESTREPO | D39: 3005163773 | E39: Calle 24 Sur 38-40
C40: FERNEY HIGUITA | D40: 5796570 | E40: CALLE 24 SUR Nº 38 - 40 | F40: 4484173 | G40: Lunes a Viernes: 8 a 12 y 2 - 5, Sabado 8 - 12 DEPOSITO $300.000
B41: BONIVENTO CASAS | D41: 3342216 | E41: Cra. 38, calle 40 b sur 98, Envigado, Antioquia | G41: Lunes a Viernes: 8 a 5, Sabado 8 - 5 DEPOSITO
A42: EL CHOCHO | B42: BOSQUE ADENTRO | C42: ROBINSON NAVAS | D42: 3363400 - 3146868123 | E42: CARRERA 27 A 36 SUR - 150 | F42: 3148204043 | G42: Lunes a Viernes de 8:30 a 5:00 pm - Sábado de 9 :00 a 12 deposito 250.000
...

Sheet PORTEROS SEDE ENVIGADO 
A1: PORTERIAS ENVIGADO
A2: NOMBRE | B2: UNIDAD | C2: N° CONTACTO | D2: ASESOR
A3: NELSON RAMIRO | B3: ST LAURENT | C3: 3128715910 | D3: JUAN PABLO VILLA | E3: 1
A4: YOHAN ESTEBAN PEREZ | B4: MISSISSIPPI DE LA CUENCA | C4: 3206234752 | D4: JUAN PABLO VILLA | E4: 2
A5: DIEGO ALEJANDRO ROJAS | B5: MAGDALENA DE LA CUENCA | C5: 3122469708 | D5: JUAN PABLO VILLA | E5: 3
A6: MILENA | B6: MAGDALENA DE LA CUENCA | C6: 3235842624 | D6: JUAN PABLO VILLA | E6: 4
A7: RAFAEL ANTONIO SANCHEZ | B7: PUERTO LUNA | C7: 3134976831 | D7: JUAN PABLO VILLA | E7: 5
A8: IVAN | B8: DOS VELAS | C8: 3192820006 | D8: JUAN PABLO VILLA | E8: 6
A9: FREIS ALBERTO MACEA | B9: O´CLOCK | C9: 3022997993 | D9: JUAN PABLO VILLA | E9: 7
A10: JORGE | B10: FORETTI | C10: 3015314482 | D10: JUAN PABLO VILLA | E10: 8
A11: JUAN ESTEBAN OCAMPO | B11: PUNTA DEL PARQUE | C11: 3206608677 | D11: JUAN PABLO VILLA | E11: 9
A12: GERLEN MENECES BEDOYA | B12: JACARANDAS | C12: 3107230505 | D12: JUAN PABLO VILLA | E12: 10
A13: GUILLERMO ORTEGA | B13: ATALAYA DE SAN JORGE | C13: 3005796328 | D13: JUAN PABLO VILLA | E13: 11
A14: DAVID ORTEGA | B14: JACARANDAS | C14: 3024648869 | D14: JUAN PABLO VILLA | E14: 12
... A111: JUAN DAVID | B111: CUBIK | C111: 3217095754 | D111: ALEJANDRO BEDOYA | E111: 109

Sheet INFORME DE RADICADOS
A1: CONTROL RADICADOS EL LIBERTADOR
A2: FECHA DE RADICADO | B2: HORA RADICADO | C2: RESPUESTA DE CONFIRMACION DE RECIBIDO | D2: HORA FECHA DE RESPUESTA | E2: RADICADO | F2: TIEMPO DE RESPUESTA FINAL
A3: 43587 | B3: 12:40 PM | C3: 13:17PM | D3: 2:44pm aplazado | E3: 6535448
A4: 43587 | B4: 15:14PM | C4: 15:20PM | D4: 17:22pm no asegurado | E4: 6537867
A5: 43587 | B5: 17:22PM | C5: 15:27PM | D5: LA PRIMERA RESPUESTA FUE EL DIA 03 DE MAYO 16:09 | E5: 6535486 | F5: EL 6 DE MAYO A LAS 8:35AM SE CONFIRMA COMO RECIBIDO EL ANEXO, RESULTADO FINALD PORQUE ESTABA PENDIENTE DE SEGUNDA HOJA DE LOS FORMULARIOS
A6: 43529 | B6: 16:54PM | C6: 11:40AM | D6: EL 6 MAYO A LAS 11:40AM ENVIARON EL RADICADO Y LA PRIMERA RESPUESTA RESPUESTA | E6: 6506028 | F6: APROBADO EL DIA 07 DE MAYO, PERO PORQUE SE ENCONTRABA EN VALIDACION TELEFONICA
A7: 43651 | B7: 3:31PM | C7: 0.64652778 | D7: 8 DE MAYO 9:56AM | E7: 6535549 | F7: 5 HORAS
A8: 43682 | B8: 2:48PM | C8: PENDIENTE | D8: PENDIENTE | E8: PENDIENTE | F8: PENDIENTE
A11: INFORME CIEN CUADRAS
A12: FECHA | B12: RADICADO | C12: CLIENTE | D12: N. TELEFONICO | E12: OBSERVACION

Sheet INFORME CLIENTES FINCA
A1: INFORME FINCA RAIZ - OLX- LONJANET 2019
A5: FECHA | B5: CODIGOS | C5: NOMBRE CLIENTE | D5: CONTACTO | E5: EJECUTIVO QUE ASIGNA | F5: ASESOR ASIGNADO | G5: OBSERVACIONES
A6: 43508 | B6: 67919072 | C6: lauchik07 | E6: MELBI CASTRILLON | F6: SEDE LAURELES | G6: EL CLIENTE SOLO BUSCA APTO POR CRISTO REY. POE ENDE SE REENVIS CORREO ALA SEDE ENCARGADA
A7: 43508 | B7: 67920860 | C7: JUAN JOSE | E7: MELBI CASTRILLON | F7: ANDRES MIRANDA | G7: SE LLAMA AL CIENTE SE LE OFRECE LAS OPCIONES DEL SECTOR Y SE LE ASIGNA EL ASESOR
A8: 43508 | C8: Ana Elisa Alvarez | E8: MELBI CASTRILLON | F8: SEDE POBLADO | G8: CLIENTE MUESTRA SU INTERES EN UN APTO DE POBALDO Y SE ENVIA CORREO A ALA SEDE ENCARGADA
A9: 43508 | B9: 67918202 | C9: JHOANA | E9: MELBI CASTRILLON | F9: JUAN DIEGO HERRERA | G9: SE LE INFORMA A LA CLIENTE QUE LA CASA YA NO ESTA DIPONIBLE PERO SE LE OFRECEN OTRAS OPCIONES
